Workbook

Sheet ที่ดินให้เช่าของกรรมการ 69
A1: รับเงินค่าเช่าส่วนตัว ปี 2568
A3: ที่ | B3: โฉนด | C3: เลขที่ดิน | D3: หน้าสำรวจ | E3: ระวาง | F3: ที่อยู่ | G3: สถานที่ | H3: กรรมสิทธิ์ | I3: เนื้อที่ | L3: รวม | M3: พื้นที่ให้เช่า | N3: ผู้เช่า | O3: เบอร์โทร | P3: เลขที่ | Q3: เงินประกัน | R3: ระยะเวลาเช่า | S3: ปี 2569 | AF3: หมายเหตุ
I4: ไร่ | J4: งาน | K4: ตร.ว. | L4: ตร.ว. | P4: สัญญา | S4: มกราคม | T4: กุมภาพันธ์ | U4: มีนาคม | V4: เมษายน | W4: พฤษภาคม | X4: มิถุนายน | Y4: กรกฎาคม | Z4: สิงหาคม | AA4: กันยายน | AB4: ตุลาคม | AC4: พฤศจิกายน | AD4: ธันวาคม | AE4: ต่อปี
A5: กรุงเทพมหานคร
A6: 1 | B6: 73811 | C6: 310 | D6: 3524 | E6: 5036 I 5824-13 | F6: 105 ซอยบรมราชชนนี 39 แขวงตลิ่งชั่น เขตตลิ่งชั่น กทม | G6: 105 หมู่ 6 หมู่บ้านปิ่นนคร | H6: คุณสมบัติ | I6: 0 | J6: 0 | K6: 18 | L6: =+I6*400+J6*100+K6 -> 18 | M6: 0-0-18 | N6: ห้องว่าง | O6: 096-995-5615 | P6: SB.65-0009 | Q6: 50000 | S6: ห้องว่าง | T6: ห้องว่าง | U6: ห้องว่าง | V6: ห้องว่าง | W6: ห้องว่าง | AF6: กสิกรไทย/บ้านโป่ง 119-3-21471-8 คุณรุจิรา เกตุสถิตย์
A7: จังหวัดกาญจนบุรี
A8: 1 | B8: 8514 | C8: 310 | D8: 3524 | E8: 5036 I 5824-13 | F8: 105 ซอยบรมราชชนนี 39 แขวงตลิ่งชั่น เขตตลิ่งชั่น กทม | G8: ที่ดินอำเภอห้วยกระเจา (ปลูกมันสำปะหลัง) | H8: คุณสมบัติ | I8: 0 | J8: 0 | K8: 18 | L8: =+I8*400+J8*100+K8 -> 18 | M8: 5-0-05 | N8: นางมุกดา ทับเปีย | O8: 096-995-5615 | P8: SB.65-0009 | Q8: 50000 | R8: 01/01/2569 - 31/12/2571 | S8: 1000 | AE8: =+S8 -> 1000 | AF8: ไทยพาณิชย์/บ้านโป่ง 611-281075-3 คุณจรรยพรรศ (ชำระรายปี)
A9: จังหวัดราชบุรี
A10: 1 | B10: 9680 | C10: 344 | D10: 1455 | E10: 4936 I 9426-02 | F10: บ้านท.3 401/1 ถนนทรงพล ต. บ้านโป่ง อ. บ้านโป่ง จ. ราชบุรี | G10: อาคารพาณิชย์ ร. 9 1 คูหา บ้านเลขที่ 28/7 | H10: คุณอยุทธ์ | I10: 0 | J10: 0 | K10: 23.4 | L10: =+I10*400+J10*100+K10 -> 23.4 | M10: 0-0-23.4 | N10: นายอริยะ ปัตตพงศ์ (คลินิกทันตกรรม) | Q10: 81000 | R10: 14/06/2564 - 13/06/2570 | S10: 27000 | T10: 27000 | U10: 27000 | V10: 27000 | W10: 27000 | AE10: =SUM(S10:AD10) -> 135000 | AF10: กสิกรไทย/บ้านโป่ง 144-2-79103-8 คุณนภา พิษณุไวศยวาท (จ่ายทุกเดือน)
A11: =+A10+1 -> 2 | B11: 5769 | C11: 427 | D11: 1061 | E11: 4936 I 9426-10 | F11: 143,145 ถนนประชานิยม ต.บ้านโป่ง อ.บ้านโป่ง จ.ราชบุรี | G11: บ้านตลาด 143-145 ให้เช่า | H11: คุณสมบัติ | I11: 0 | J11: 0 | K11: 21.9 | L11: =+I11*400+J11*100+K11 -> 21.9 | M11: 0-0-21.9 | N11: นายศิรภพ วิยาภรณ์ (ร้านนวด) | O11: 062-628-5195 | P11: SB.65-0010 | Q11: 30000 | R11: 01/01/2569 - 31/12/2571 | S11: 18150 | T11: 18150 | U11: 18150 | V11: 18150 | W11: 18150 | AE11: =SUM(S11:AD11) -> 90750 | AF11: ไทยพาณิชย์/บ้านโป่ง 611-281075-3 คุณจรรยพรรศ (จ่ายทุกเดือน)
A12: =+A11+1 -> 3 | B12: 4718 | C12: 776 | D12: 807 | E12: 4936 I 9426-06 | F12: เลขที่ 200,202 อาคารพาณิชย์ 2 คูหา 3 ชั้น ถนนแสงชูโต ต. บ้านโป่ง อ. บ้านโป่ง จ. ราชบุรี | G12: ให้ DTAC เช่าในนามน.ส. ภาวิณี วังมะนาว | H12: คุณสมบัติ | I12: 0 | J12: 0 | K12: 27.4 | L12: =+I12*400+J12*100+K12 -> 27.4 | M12: 0-0-27.4 | N12: บริษัท ดีแทค ไตรเน็ต จำกัด | O12: 081-655-2552 | P12: - | Q12: 105000 | R12: 01/11/2568 - 31/10/2571 | S12: 40000 | T12: 40000 | U12: 40000 | V12: 40000 | W12: 40000 | X12: 40000 | Y12: 40000 | Z12: 40000 | AA12: 40000 | AB12: 40000 | AE12: =SUM(S12:AD12) -> 400000 | AF12: จ่ายภายในวันที่ 5 พฤศจิกายน ของทุกปี
A13: =+A12+1 -> 4 | B13: 10180 | C13: 344 | D13: 1455 | E13: 4936 I 9426-02 | F13: บ้านท.3 401/1 ถนนทรงพล ต. บ้านโป่ง อ. บ้านโป่ง จ. ราชบุรี | G13: บ้านท.3 401/1 ถนนทรงพล ต. บ้านโป่ง (บ้านร้านเพลง) | H13: คุณอยุทธ์ | I13: 0 | J13: 0 | K13: 96.2 | L13: =+I13*400+J13*100+K13 -> 96.2 | M13: 0-0-96.2 | N13: นางนาถตยา มหพันธ์ | Q13: 10000 | R13: 01/01/2569 - 31/12/2571 | S13: 5324 | T13: 5324 | U13: 5324 | V13: 5324 | W13: 5324 | AE13: =SUM(S13:AD13) -> 26620 | AF13: ไทยพาณิชย์/บ้านโป่ง 611-281075-3 คุณจรรยพรรศ (จ่ายทุกเดือน)
A14: =+A13+1 -> 5 | F14: บ้านท.3 401/2 ถนนทรงพล ต. บ้านโป่ง อ. บ้านโป่ง จ. ราชบุรี | G14: บ้านท.3 401/2 ถนนทรงพล ต. บ้านโป่ง | L14: =+I14*400+J14*100+K14 -> 0 | N14: น.ส.อาพร กลัดกลิ่น | O14: 081-526-3202 | P14: SB.65-0008 | Q14: 10000 | R14: 01/01/2569 - 31/12/2571 | S14: 5324 | T14: 5324 | U14: 5324 | V14: 5324 | W14: 5324 | AE14: =SUM(S14:AD14) -> 26620 | AF14: ไทยพาณิชย์/บ้านโป่ง 611-281075-3 คุณจรรยพรรศ (จ่ายทุกเดือน)
A15: =+A14+1 -> 6 | G15: ค่ายหลวง | M15: ขายก๋วยเตี๋ยว | N15: น.ส. เพียงตวัน อารีย์ | Q15: - | R15: 11/03/2564 - 31/05/2569 | S15: 3800 | T15: 3800 | U15: 3800 | V15: 3800 | W15: 3800 | AE15: =SUM(S15:AD15) -> 19000 | AF15: ไทยพาณิชย์/บ้านโป่ง 611-281075-3 คุณจรรยพรรศ (จ่ายทุกเดือน)
A16: 7 | G16: ค่ายหลวง | M16: ขายน้ำกระท่อม | N16: นายวรพล แม้นจิตต์ | R16: 16/02/2568 - 31/05/2569 | S16: 7348 | T16: 6748 | U16: 7476 | V16: 7548 | W16: 7380 | AE16: =SUM(S16:AD16) -> 36500 | AF16: ไทยพาณิชย์/บ้านโป่ง 611-281075-3 คุณจรรยพรรศ (จ่ายทุกเดือน)
A17: 8 | G17: ค่ายหลวง | M17: ขายหมูกระทะ | N17: นางสาวภิญญ์วิภา ตามิ | R17: 01/03/2568 - 31/05/2569 | S17: 4608 | T17: 4008 | U17: 4120 | V17: 4888 | W17: 5360 | AE17: =SUM(S17:AD17) -> 22984 | AF17: ไทยพาณิชย์/บ้านโป่ง 611-281075-3 คุณจรรยพรรศ (จ่ายทุกเดือน)
A18: 9 | G18: ค่ายหลวง | M18: ขายเบอร์เกอร์รี่ | N18: น.ส. ธิดารัตน์ ตันชัยสวัสดิ์ | R18: 01/05/2568 - 31/05/2569 | S18: 7648 | T18: 7240 | U18: 4592 | V18: 7456 | W18: 7728 | AE18: =SUM(S18:AD18) -> 34664 | AF18: ไทยพาณิชย์/บ้านโป่ง 611-281075-3 คุณจรรยพรรศ (จ่ายทุกเดือน)
A19: 10 | B19: 7449 | C19: 247 | D19: 275 | E19: 4936 I 9032 | F19: ต.ท่าผา อ.บ้านโป่ง จ.ราชบุรี | G19: วัดโกสินาราย์ ท่าผา | H19: คุณณัฐวุฒิ,คุณอยุทธ์,คุณจันทาภา | I19: 35 | J19: 0 | K19: 32 | L19: =+I19*400+J19*100+K19 -> 14032 | M19: 30-0-0 | N19: นายทรงพล หมื่นแก้ว | P19: SB.65-0017 | R19: 01/01/2569 - 31/12/2569 | S19: 6000 | T19: 6000 | U19: 6000 | V19: 6000 | W19: 6000 | X19: 6000 | AE19: =SUM(S19:AD19) -> 36000 | AF19: ไทยพาณิชย์/บ้านโป่ง 611-281075-3 คุณจรรยพรรศ (จ่ายทุก 3 เดือน)
A20: =+A19+1 -> 11 | B20: 7655 | C20: 6 | D20: 25 | E20: 4936 I 9638 | F20: ต.กรับใหญ่ อ.บ้านโป่ง จ.ราชบุรี | G20: กรับใหญ่ | H20: คุณอยุทธ์ | I20: 15 | J20: 1 | K20: 61 | L20: =+I20*400+J20*100+K20 -> 6161 | M20: 15-1-61 | N20: นายธนากร วงษ์พิทักษ์โรจน์ | O20: - | P20: SB64-10-001 | Q20: 0 | R20: 01/01/2566 - 31/12/2567 | AE20: =SUM(S20:AD20) -> 0 | AF20: ไทยพาณิชย์/บ้านโป่ง 611-281075-3 คุณจรรยพรรศ (จ่ายปีละ 1 ครั้ง)
A21: รวม | S21: =SUM(S10:S20) -> 125202 | T21: =SUM(T10:T20) -> 123594 | U21: =SUM(U10:U20) -> 121786 | V21: =SUM(V10:V20) -> 125490 | W21: =SUM(W10:W20) -> 126066 | X21: =SUM(X10:X20) -> 46000 | Y21: =SUM(Y10:Y20) -> 40000 | Z21: =SUM(Z10:Z20) -> 40000 | ... AE21: =SUM(AE10:AE20) -> 828138
A22: จังหวัดเชียงใหม่
A23: 1 | B23: 14408 | F23: ต.ช้างเผือก อ.เมืองเชียงใหม่ จ.เชียงใหม่ | G23: 107/11 ซ.4 ถนนช้างเผือก ต. ศรีภูมิ อ. เมืองเชียงใหม่ จ.เชียงใหม่ | N23: คุณจินดา โกพลรัตน์ (ผู้เช่าใหม่) | O23: 081-026-9494 | P23: SB.65-0001 | Q23: 10000 | R23: 09/09/2568 -31/1/2571 | S23: 6500 | T23: 6500 | U23: 6500 | V23: 6500 | W23: ค้างจ่าย | AE23: =SUM(S23:AD23) -> 26000 | AF23: กสิกรไทย/บ้านโป่ง 119-3-21759-8 น.ส.ภาวิณี วังมะนาว (จ่ายทุกเดือน)
A24: 2 | B24: 21845 | C24: 496 | D24: 3469 | E24: 4746 I 9878-2 | F24: ต.ช้างเผือก อ.เมืองเชียงใหม่ จ.เชียงใหม่ | G24: แยกข่วงสิงห์ อู่ซ่อมรถยนต์,บ้านเช่า เชียงใหม่ | H24: คุณสมบัติ,คุณนภา,คุณณัฐวุฒิ | I24: 0 | J24: 2 | K24: 55 | L24: =+I24*400+J24*100+K24 -> 255 | M24: 0-2-55 | N24: คุณกมลวรรณ กลอนกลาง | O24: 093-145-2120 | P24: SB.65-0006 | Q24: 40000 | R24: 01/01/2569 - 31/12/2571 | S24: 46200 | T24: 46200 | U24: 46200 | V24: 46200 | W24: 46200 | AE24: =SUM(S24:AD25) -> 231000 | AF24: กสิกรไทย/บ้านโป่ง 119-3-21471-8 คุณรุจิรา เกตุสถิตย์ (จ่ายทุกเดือน)
B25: 21844 | C25: 498 | D25: 3468 | E25: 4746 I 9878-2 | F25: ต.ช้างเผือก อ.เมืองเชียงใหม่ จ.เชียงใหม่ | G25: แยกข่วงสิงห์ อู่ซ่อมรถยนต์,บ้านเช่า เชียงใหม่ | H25: คุณสมบัติ,คุณนภา,คุณณัฐวุฒิ | I25: 0 | J25: 2 | K25: 19 | L25: =+I25*400+J25*100+K25 -> 219 | M25: 0-2-19
A26: 3 | B26: 28402 | C26: 1207 | D26: 703 | E26: 4846 IV 0078-8 | F26: ต.ฟ้าฮ่าม อ.เมืองเชียงใหม่ จ.เชียงใหม่ | G26: อู่ซ่อมรถยนต์ เชียงใหม่ | H26: คุณสมบัติ | I26: 0 | J26: 2 | K26: 44 | L26: =+I26*400+J26*100+K26 -> 244 | M26: 0-2-44 | N26: นายสมชัย พาราสรรเสริญ (เช่าใหม่) | O26: 089-5580708 | P26: SB.65-0004 | Q26: - | R26: 01/01/2569 - 31/12/2571 | S26: 10648 | T26: 10648 | U26: 10648 | V26: 10648 | W26: 10648 | AE26: =SUM(S26:AD26) -> 53240 | AF26: กสิกรไทย/บ้านโป่ง 119-3-21759-8 น.ส.ภาวิณี วังมะนาว (จ่ายทุกเดือน)
A27: 5 | B27: 14407 | C27: 4480 | D27: 2054 | E27: 4746 I 9878-14 | F27: ต.ช้างเผือก อ.เมืองเชียงใหม่ จ.เชียงใหม่ | G27: ที่จอดรถ เชียงใหม่ | H27: คุณสมบัติ | I27: 0 | J27: 0 | K27: 98 | L27: =+I27*400+J27*100+K27 -> 98 | M27: 0-0-98 | N27: นางอารี อุ่นแสง | P27: SB.65-0002 | Q27: 10000 | R27: 01/01/2569 - 31/12/2571 | S27: 7986 | T27: 7986 | U27: 7986 | V27: 7986 | W27: 7986 | AE27: =SUM(S27:AD27) -> 39930 | AF27: กสิกรไทย/บ้านโป่ง 119-3-21759-8 น.ส.ภาวิณี วังมะนาว (จ่ายทุกเดือน)
A28: 6 | B28: 14408 | C28: 4481 | D28: 2055 | E28: 4746 I 9878-14 | F28: ต.ช้างเผือก อ.เมืองเชียงใหม่ จ.เชียงใหม่ | G28: ทาวน์เฮ้าส์ เชียงใหม่ 107/12 ซ.4 ถนนช้างเผือก ต. ศรีภูมิ อ. เมืองเชียงใหม่ จ.เชียงใหม่ | H28: คุณสมบัติ | I28: 0 | J28: 0 | K28: 98 | L28: =+I28*400+J28*100+K28 -> 98 | M28: 0-0-98 | N28: นายสิริชัย นครสิงห์ | O28: 088-577-1271 | P28: SB.65-0003 | Q28: 10000 | R28: 01/01/2569 - 31/12/2571 | S28: 7986 | T28: 7986 | U28: 7986 | V28: 7986 | W28: 7986 | AE28: =SUM(S28:AD28) -> 39930 | AF28: กสิกรไทย/บ้านโป่ง 119-3-21759-8 น.ส.ภาวิณี วังมะนาว (จ่ายทุกเดือน)
A29: =+A28+1 -> 7 | B29: 24560 | C29: 4606 | D29: 4102 | E29: 4746 I 9878-14 | F29: 60/10-11 ถนนช้างเผือก | G29: SN อพาร์ทเม้นท์ (สาขาเชียงใหม่) | H29: คุณจันทาภา | I29: 0 | J29: 0 | K29: 20 | L29: =+I29*400+J29*100+K29 -> 20 | M29: 0-0-20 | N29: น.ส.นวรัตน์ เกตตะพันธุ์ (คุณปิติ) | O29: 087-656-9245 | Q29: 60000 | R29: 01/01/2569 - 31/12/2571 | S29: 60000 | T29: 60000 | U29: 60000 | V29: 60000 | W29: 60000 | AE29: =SUM(S29:AD30) -> 300000 | AF29: กสิกรไทย/บ้านโป่ง 119-3-21759-8 น.ส.ภาวิณี วังมะนาว (จ่ายทุกเดือน)
A30: =+A29+1 -> 8 | B30: 24559 | C30: 4605 | D30: 4101 | E30: 4746 I 9878-14 | F30: 60/10-11 ถนนช้างเผือก | G30: SN อพาร์ทเม้นท์ (สาขาเชียงใหม่) | H30: คุณสมบัติ | I30: 0 | J30: 0 | K30: 49 | L30: =+I30*400+J30*100+K30 -> 49 | M30: 0-0-49 | N30: ร้านวาเลนไทน์ เชียงใหม่ ชั้น 1
A31: รวม | S31: =SUM(S23:S30) -> 139320 | T31: =SUM(T23:T30) -> 139320 | U31: =SUM(U23:U30) -> 139320 | V31: =SUM(V23:V30) -> 139320 | W31: =SUM(W23:W30) -> 132820 | X31: =SUM(X23:X30) -> 0 | Y31: =SUM(Y23:Y30) -> 0 | Z31: =SUM(Z23:Z30) -> 0 | ... AE31: =SUM(AE23:AE30) -> 690100
A32: บ่อทราย
A33: บ่อทรายหนองสาหร่ายเก่า
A34: 1 | B34: นส.3 ก 2783 | C34: 95 | D34: 33 | E34: 4937/// | F34: ต.ดอนเจดีย์ อ.พนมทวน จ.กาญจนบุรี | G34: บ่อทรายหนองสาหร่าย | H34: คุณสมบัติ | I34: 9 | J34: 2 | K34: 58 | L34: =+I34*400+J34*100+K34 -> 3858 | M34: 2-0-0 | N34: นายสมปอง กระต่ายทอง | P34: SB65.0013 | R34: 01/01/2569 - 31/12/2569 | S34: 400 | T34: 400 | U34: 400 | V34: 400 | W34: 400 | X34: 400 | Y34: 400 | Z34: 400 | AA34: 400 | AB34: 400 | AC34: 400 | AD34: 400 | AE34: =SUM(S34:AD34) -> 4800 | AF34: ไทยพาณิชย์/บ้านโป่ง 611-281075-3 คุณจรรยพรรศ (จ่ายปีละ 1 ครั้ง)
A35: บ่อทรายบ้านยาง
A36: 1 | B36: 29913 | C36: 83 | D36: 261 | E36: 4936 I 0030 | F36: ต.บ้านยาง อ.เมืองนครปฐม จ.นครปฐม | G36: บ่อทรายบ้านยาง | H36: คุณณัฐวุฒิ,คุณจันทาภา,คุณอยุทธ์ | I36: 7 | J36: 1 | K36: 85.8 | L36: =+I36*400+J36*100+K36 -> 2985.8 | M36: 7-2-0 | N36: นางนัยณา สีดา | O36: 083-228-1016 | P36: SB65-0014 | R36: 01/01/2569 - 31/12/2569 | S36: 1500 | T36: 1500 | U36: 1500 | V36: 1500 | W36: 1500 | X36: 1500 | AE36: =SUM(S36:AD36) -> 9000 | AF36: ไทยพาณิชย์/บ้านโป่ง 611-281075-3 คุณจรรยพรรศ (จ่ายทุก 6 เดือน)
A37: บ่อทรายสระตาสัง
A38: 1 | B38: นส.3 | C38: 4 | D38: 71 | F38: ต.บ้านยาง อ.เมืองนครปฐม จ.นครปฐม | G38: บ่อทรายสระตาสัง | H38: คุณณัฐวุฒิ,คุณจันทาภา,คุณอยุทธ์ | I38: 11 | J38: 2 | K38: 0 | L38: =+I38*400+J38*100+K38 -> 4600 | M38: 3-0-0 | N38: นางนัยณา สีดา | O38: 083-228-1016 | P38: SB65-0015 | R38: 01/01/2569 - 31/12/2569 | S38: 600 | T38: 600 | U38: 600 | V38: 600 | W38: 600 | X38: 600 | AE38: =SUM(S38:AD38) -> 3600 | AF38: ไทยพาณิชย์/บ้านโป่ง 611-281075-3 คุณจรรยพรรศ (จ่ายทุก 6 เดือน)
A39: จังหวัดชุมพร
A40: 1 | B40: 24265 | C40: 515 | D40: 65 | E40: 4829 IV 3050-1 | F40: ต.หาดทรายรี อ.เมืองชุมพร จ.ชุมพร | G40: หาดทรายรี | H40: คุณณัฐวุฒิ-คุณจันทาภา-คุณอยุทธ์ | I40: 7 | J40: 2 | K40: 52.1 | L40: =+I40*400+J40*100+K40 -> 3052.1 | M40: เช่าบางส่วน | N40: บจ. ช.ฐานเพชร คอนสตรัคชั่น | R40: 15/12/2566 - 31/05/2567 | AE40: =SUM(S40:AD41) -> 0 | AF40: กสิกรไทย/บ้านโป่ง 144-2-79103-8 คุณนภา พิษณุไวศยวาท
A41: 2 | B41: 28655 | C41: 517 | D41: 143 | E41: 4829 IV 3050-1 | F41: ต.หาดทรายรี อ.เมืองชุมพร จ.ชุมพร | G41: หาดทรายรี | H41: คุณณัฐวุฒิ-คุณจันทาภา-คุณอยุทธ์ | I41: 1 | J41: 1 | K41: 44.9 | L41: =+I41*400+J41*100+K41 -> 544.9
...

Sheet ค่าเช่าซอยมายเฮ้าส์
A1: ค่าเช่าซอยมายเฮ้าส์
A2: ประจำเดือนพฤษภาคม 2569 บัญชี SCB น.ส. ภาวินี จอมพล 611-281071-1
A4: เลขห้อง | B4: รายชื่อ | C4: เงินประกัน | D4: มัดจำ | E4: ค่าเช่า | F4: ค่าน้ำ | G4: ค่าไฟฟ้า | H4: รายได้ค่าบริการ | I4: ยอดค้างจ่าย | J4: ค่าปรับ | K4: รวม | L4: รับเงินวันที่
A5: BP35/533 | B5: คุณณัชชา โสไกร ย้ายมาจาก 536 | E5: 1200 | F5: 270 | G5: 1400 | H5: 25 | K5: =SUM(C5:J5) -> 2895 | L5: 244483
A6: BP35/534 | B6: คุณภานุพงษ์ เพชรทอง | E6: 1300 | F6: 54 | G6: 272 | H6: 25 | K6: =SUM(C6:J6) -> 1651 | L6: 244479
A7: BP35/535 | B7: PHAM DINH TOA | E7: 1200 | F7: 90 | G7: 952 | H7: 25 | K7: =SUM(C7:J7) -> 2267 | L7: 244474
A8: BP35/536 | B8: คุณฐิติรัตน์ มั่งคง | E8: 1300 | F8: 162 | G8: 5128 | H8: 25 | K8: =SUM(C8:J8) -> 6615 | L8: 244479
A9: BP35/537 | B9: คุณธนพงษ์ พลอยพลาย | E9: 1300 | F9: 252 | G9: 456 | H9: 25 | K9: =SUM(C9:J9) -> 2033 | L9: 244471
A10: BP35/538 | B10: ห้องว่าง (ไม่มีมิเตอร์ไฟ) | K10: =SUM(C10:J10) -> 0
A11: BP35/539 | B11: คุณทัศนีย์ อำนวยสุนทร | E11: 1200 | F11: 108 | G11: 192 | H11: 25 | K11: =SUM(C11:J11) -> 1525 | L11: 244479
A12: BP35/540 | B12: AUNG ZIN | E12: 1300 | F12: 54 | G12: 240 | H12: 25 | K12: =SUM(C12:J12) -> 1619 | L12: 244474
A13: BP35/541 | B13: THAY HTAY LIN | C13: 2600 | E13: 1300 | K13: =SUM(C13:J13) -> 3900 | L13: 244469
A14: BP35/542 | B14: นายรันต์ นางโช | E14: 1300 | F14: 144 | G14: 408 | H14: 25 | J14: 100 | K14: =SUM(C14:J14) -> 1977 | L14: 244480
A15: BP35/543 | B15: คุณมานะ สามชัย | E15: 1300 | F15: 108 | G15: 240 | H15: 25 | K15: =SUM(C15:J15) -> 1673 | L15: 244480
A16: BP35/544 | B16: คุณบุญสม หมูขาว | E16: 1200 | F16: 180 | G16: 640 | H16: 25 | K16: =SUM(C16:J16) -> 2045 | L16: 244480
A17: BP35/545 | B17: คุณจันทร์ดี จอกจันทร์ | E17: 1200 | F17: 324 | G17: 1064 | H17: 25 | K17: =SUM(C17:J17) -> 2613 | L17: 244479
A18: BP35/546 | B18: MYINT THEIN | E18: 1300 | F18: 50 | G18: 224 | H18: 25 | K18: =SUM(C18:J18) -> 1599 | L18: 244477
A19: BP35/547 | B19: KO WIN | E19: 1200 | F19: 288 | G19: 552 | H19: 25 | K19: =SUM(C19:J19) -> 2065 | L19: 244477
A20: BP35/548 | B20: คุณภีรพร กลัดขวัญ | E20: 1200 | F20: 50 | G20: 536 | H20: 25 | K20: =SUM(C20:J20) -> 1811 | L20: 244476
A21: รวมทั้งสิ้น | C21: =SUM(C5:C20) -> 2600 | D21: =SUM(D5:D20) -> 0 | E21: =SUM(E5:E20) -> 18800 | F21: =SUM(F5:F20) -> 2134 | G21: =SUM(G5:G20) -> 12304 | H21: =SUM(H5:H20) -> 350 | I21: =SUM(I5:I20) -> 0 | J21: =SUM(J5:J20) -> 100 | K21: =SUM(K5:K20) -> 36288
B24: สรุป | C24: ห้องทั้งหมด | D24: มีผู้เช่า | E24: เข้าใหม่ | F24: ย้ายออก,ริบเงิน | G24: ห้องว่างทั้งหมด
B25: มกราคม | C25: 16 | D25: 14 | F25: 1 | G25: 3 | H25: ห้องว่าง 538,541,542
B26: กุมภาพันธ์ | C26: 16 | D26: 13 | G26: 3 | H26: ห้องว่าง 538,541,542
B27: มีนาคม | C27: 16 | D27: 13 | G27: 3 | H27: ห้องว่าง 538,541,542
B28: เมษายน | C28: 16 | D28: 13 | E28: 1 | G28: 2 | H28: ห้องว่าง 538,541
B29: พฤษภาคม | C29: 16 | D29: 14 | E29: 1 | G29: 1 | H29: ห้องว่าง 538
B30: มิถุนายน | G30: 1
B31: กรกฎาคม | G31: 1
B32: สิงหาคม | G32: 1
B33: กันยายน | G33: 1
B34: ตุลาคม | G34: 1
B35: พฤศจิกายน | G35: 2
B36: ธันวาคม | G36: 2

Sheet ที่ดินไม่มีผู้เช่า
A1: บัญชีที่ดินกรรมการ
A3: ที่ | B3: โฉนด | C3: เลขที่ดิน | D3: หน้าสำรวจ | E3: ระวาง | F3: ที่อยู่ | G3: สถานที่ | H3: กรรมสิทธิ์ | I3: เนื้อที่ | L3: รวม | M3: พื้นที่ให้เช่า | N3: ผู้เช่า | O3: เบอร์โทร | P3: เลขที่ | Q3: เงินประกัน | R3: ระยะเวลาเช่า | S3: ปี 2564 | AF3: หมายเหตุ
I4: ไร่ | J4: งาน | K4: ตร.ว. | L4: ตร.ว. | P4: สัญญา | S4: มกราคม | T4: กุมภาพันธ์ | U4: มีนาคม | V4: เมษายน | W4: พฤษภาคม | X4: มิถุนายน | Y4: กรกฎาคม | Z4: สิงหาคม | AA4: กันยายน | AB4: ตุลาคม | AC4: พฤศจิกายน | AD4: ธันวาคม | AE4: ต่อปี
A5: กรุงเทพมหานคร
A6: 1 | B6: 73811 | C6: 310 | D6: 3524 | E6: 5036 I 5824-13 | F6: 105 ซอยบรมราชชนนี 39 แขวงตลิ่งชั่น เขตตลิ่งชั่น กทม | G6: 105 หมู่ 6 หมู่บ้านปิ่นนคร | H6: คุณสมบัติ | I6: 0 | J6: 0 | K6: 18 | L6: =+I6*400+J6*100+K6 -> 18 | M6: 0-0-18 | AE6: =SUM(S6:AD6) -> 0
A7: จังหวัดราชบุรี
A8: 1 | B8: 10081 | C8: 379 | D8: 572 | E8: 15 น/4 อ. | F8: ต.คุ้งพยอม อ.บ้านโป่ง จ.ราชบุรี | G8: ที่ดินริมน้ำคุ้งพยอม | H8: คุณสมบัติ | I8: 4 | J8: 3 | K8: 17 | L8: =+I8*400+J8*100+K8 -> 1917
A9: 2 | B9: 68042 | C9: 427 | D9: 6275 | E9: 4936 I 9228-15 | F9: 190/60 หมู่ 4 ต. เบิกไพร อ. บ้านโป่ง | G9: บ้าน อ. ต้อย 190/60 หมู่ 4 ต. เบิกไพร อ. บ้านโป่ง | H9: คุณอยุทธ์ | I9: 0 | J9: 0 | K9: 52 | L9: =+I9*400+J9*100+K9 -> 52 | AE9: =SUM(S9:AD9) -> 0
A10: =+A9+1 -> 3 | B10: 7975 | C10: 37 | D10: 1768 | E10: 4936 I 9426-03 | F10: ต.ปากแรต อ.บ้านโป่ง จ.ราชบุรี | G10: ข้างท.3 | H10: คุณสมบัติ,คุณนภา | I10: 0 | J10: 3 | K10: 76 | L10: =+I10*400+J10*100+K10 -> 376
A11: =+A10+1 -> 4 | B11: 19003 | C11: 39 | D11: 4501 | E11: 4936 I 9426-03 | F11: ต.ปากแรต อ.บ้านโป่ง จ.ราชบุรี | G11: ข้างท.3 (ที่สวนผัก หลังทางรถไฟ) | H11: คุณสมบัติ | I11: 0 | J11: 3 | K11: 88 | L11: =+I11*400+J11*100+K11 -> 388
A12: =+A11+1 -> 5 | B12: 19004 | C12: 40 | D12: 4502 | E12: 4936 I 9426-03 | F12: ต.ปากแรต อ.บ้านโป่ง จ.ราชบุรี | G12: ข้างท.3 (ที่สวนผัก หลังทางรถไฟ) | H12: คุณสมบัติ | I12: 0 | J12: 3 | K12: 87 | L12: =+I12*400+J12*100+K12 -> 387
A13: =+A12+1 -> 6 | B13: 19005 | C13: 41 | D13: 4503 | E13: 4936 I 9426-03 | F13: ต.ปากแรต อ.บ้านโป่ง จ.ราชบุรี | G13: ข้างท.3 (ที่สวนผัก หลังทางรถไฟ) | H13: คุณสมบัติ | I13: 0 | J13: 3 | K13: 87 | L13: =+I13*400+J13*100+K13 -> 387
A14: =+A13+1 -> 7 | B14: 31628 | C14: 38 | D14: 6624 | E14: 4936 I 9426-03 | F14: ต.ปากแรต อ.บ้านโป่ง จ.ราชบุรี | G14: ข้างท.3 | H14: คุณสมบัติ,คุณนภา | I14: 1 | J14: 0 | K14: 0 | L14: =+I14*400+J14*100+K14 -> 400
A15: =+A14+1 -> 8 | B15: 3355 | C15: 81 | D15: 169 | E15: 4936 I 9426-8 | F15: ต.บ้านโป่ง อ.บ้านโป่ง จ.ราชบุรี | G15: ข้าง TMK | H15: คุณสมบัติ,คุณนภา,คุณณัฐวุฒิ,คุณจันทาภา,คุณอยุทธ์ | I15: 0 | J15: 1 | K15: 51 | L15: =+I15*400+J15*100+K15 -> 151
A16: =+A15+1 -> 9 | B16: 1107 | C16: 246 | D16: 2723 | E16: 4937 I 9426-8 | F16: ต.บ้านโป่ง อ.บ้านโป่ง จ.ราชบุรี | G16: ข้าง TMK | H16: คุณสมบัติ,คุณนภา,คุณณัฐวุฒิ,คุณจันทาภา,คุณอยุทธ์ | I16: 0 | J16: 0 | K16: 59 | L16: =+I16*400+J16*100+K16 -> 59
A17: =+A16+1 -> 10 | B17: 1108 | C17: 247 | D17: 7824 | E17: 4938 I 9426-8 | F17: ต.บ้านโป่ง อ.บ้านโป่ง จ.ราชบุรี | G17: ข้าง TMK | H17: คุณสมบัติ,คุณนภา,คุณณัฐวุฒิ,คุณจันทาภา,คุณอยุทธ์ | I17: 0 | J17: 0 | K17: 60 | L17: =+I17*400+J17*100+K17 -> 60
A18: =+A17+1 -> 11 | B18: 1109 | C18: 248 | D18: 7825 | E18: 4939 I 9426-8 | F18: ต.บ้านโป่ง อ.บ้านโป่ง จ.ราชบุรี | G18: ข้าง TMK | H18: คุณสมบัติ,คุณนภา,คุณณัฐวุฒิ,คุณจันทาภา,คุณอยุทธ์ | I18: 0 | J18: 0 | K18: 61 | L18: =+I18*400+J18*100+K18 -> 61
A19: =+A18+1 -> 12 | B19: 1110 | C19: 249 | D19: 7826 | E19: 4940 I 9426-8 | F19: ต.บ้านโป่ง อ.บ้านโป่ง จ.ราชบุรี | G19: ข้าง TMK | H19: คุณสมบัติ,คุณนภา,คุณณัฐวุฒิ,คุณจันทาภา,คุณอยุทธ์ | I19: 0 | J19: 0 | K19: 62 | L19: =+I19*400+J19*100+K19 -> 62
A20: =+A19+1 -> 13 | B20: 1111 | C20: 250 | D20: 7827 | E20: 4941 I 9426-8 | F20: ต.บ้านโป่ง อ.บ้านโป่ง จ.ราชบุรี | G20: ข้าง TMK | H20: คุณสมบัติ,คุณนภา,คุณณัฐวุฒิ,คุณจันทาภา,คุณอยุทธ์ | I20: 0 | J20: 0 | K20: 63 | L20: =+I20*400+J20*100+K20 -> 63
A21: =+A20+1 -> 14 | B21: 11250 | C21: 85 | D21: 1298 | E21: 4936 I 9426-8 | F21: ต.บ้านโป่ง อ.บ้านโป่ง จ.ราชบุรี | G21: หลัง TMK | H21: คุณณัฐวุฒิ,คุณจันทาภา,คุณอยุทธ์ | I21: 2 | J21: 2 | K21: 9.7 | L21: =+I21*400+J21*100+K21 -> 1009.7
... A28: =+A27+1 -> 21 | B28: 67122 | C28: 699 | D28: 1857 | E28: 4936 I 9822 | F28: ต.ดอนกระเบื้อง อ.บ้านโป่ง จ.ราชบุรี | G28: ดอนกระเบื้อง (คุณหมวย โซล่า) | H28: คุณจันทาภา,คุณอยุทธ์,คุณณัฐวุฒิ | I28: 1 | J28: 3 | K28: 46 | L28: =+I28*400+J28*100+K28 -> 746
H29: คุณจิตรา,คุณน้ำผึ้ง,คุณจตุรพร | L29: =+I29*400+J29*100+K29 -> 0
H30: คุณอัจฉรา,สุรีพร | L30: =+I30*400+J30*100+K30 -> 0
A31: =+A28+1 -> 22 | B31: 67121 | C31: 687 | D31: 1792 | E31: 4936 I 9822 | F31: ต.ดอนกระเบื้อง อ.บ้านโป่ง จ.ราชบุรี | G31: ดอนกระเบื้อง (คุณหมวย โซล่า) | H31: คุณจันทาภา,คุณอยุทธ์,คุณณัฐวุฒิ,คุณน้ำผึ้ง | I31: 4 | J31: 3 | K31: 84 | L31: =+I31*400+J31*100+K31 -> 1984
A32: =+A31+1 -> 23 | B32: 76633 | C32: 724 | D32: 4691 | E32: 4936 I 0028 | F32: ต.หนองกบ อ.บ้านโป่ง จ.ราชบุรี | G32: หนองกบ | H32: คุณณัฐวุฒิ,คุณอยุทธ์,คุณจันทาภา | I32: 2 | J32: 0 | K32: 63 | L32: =+I32*400+J32*100+K32 -> 863
A33: =+A32+1 -> 24 | B33: 1409 | C33: 298 | D33: 277 | E33: 4936 I 9224-00 | F33: ต. สวนกล้วย อ.บ้านโป่ง จ.ราชบุรี | G33: หลังร้านเจียบ่วยเฮียง | H33: คุณอยุทธ์ | I33: 1 | J33: 0 | K33: 23 | L33: =+I33*400+J33*100+K33 -> 423
A34: =+A33+1 -> 25 | B34: 74561 | C34: 907 | D34: 7667 | E34: 4936 I 9232 | F34: ต.ท่าผา อ.บ้านโป่ง จ.ราชบุรี | G34: ท่าผา | H34: คุณอยุทธ์ | I34: 0 | J34: 1 | K34: 78 | L34: =+I34*400+J34*100+K34 -> 178
A35: =+A34+1 -> 26 | B35: 24381 | C35: 3 | D35: 4656 | E35: 4936 I 9428-14 | F35: ต.บ้านโป่ง อ.บ้านโป่ง จ.ราชบุรี | G35: ข้างสระว่ายน้ำเทศบาล (ศูนย์เยาวชน) | H35: คุณณัฐวุฒิ,คุณจันทาภา,คุณอยุทธ์ | I35: 2 | J35: 3 | K35: 94.5 | L35: =+I35*400+J35*100+K35 -> 1194.5
A36: จังหวัดชลบุรี
A37: 1 | B37: 1311 | C37: 6 | D37: 2153 | E37: 5235 IIII 4054 | F37: ต.คลองกิ่ว อ.บ้านบึง จ.ชลบุรี | G37: อยู่ในสนามกอล์ฟ | H37: คุณสมบัติ | I37: 2 | J37: 2 | K37: 13 | L37: =+I37*400+J37*100+K37 -> 1013
A38: จังหวัดชุมพร
A39: 1 | B39: 18748 | C39: 26 | D39: 1 | E39: 24 น./16 อ./3 | F39: ต.หาดทรายรี อ.เมืองชุมพร จ.ชุมพร | G39: หาดทรายรี | H39: คุณณัฐวุฒิ-คุณจันทาภา-คุณอยุทธ์ | I39: 0 | J39: 2 | K39: 53.6 | L39: =+I39*400+J39*100+K39 -> 253.6
A40: =+A39+1 -> 2 | B40: 19481 | C40: 513 | D40: 8 | E40: 4829 IV 3050-1 | F40: ต.หาดทรายรี อ.เมืองชุมพร จ.ชุมพร | G40: หาดทรายรี | H40: คุณณัฐวุฒิ-คุณจันทาภา-คุณอยุทธ์ | I40: 0 | J40: 0 | K40: 60.9 | L40: =+I40*400+J40*100+K40 -> 60.9
A41: =+A40+1 -> 3 | B41: 19480 | C41: 514 | D41: 7 | E41: 4829 IV 3050-1 | F41: ต.หาดทรายรี อ.เมืองชุมพร จ.ชุมพร | G41: หาดทรายรี | H41: คุณณัฐวุฒิ-คุณจันทาภา-คุณอยุทธ์ | I41: 0 | J41: 0 | K41: 50.4 | L41: =+I41*400+J41*100+K41 -> 50.4
A42: =+A41+1 -> 4 | B42: 19482 | C42: 512 | D42: 9 | E42: 4829 IV 3050-1 | F42: ต.หาดทรายรี อ.เมืองชุมพร จ.ชุมพร | G42: หาดทรายรี | H42: คุณณัฐวุฒิ-คุณจันทาภา-คุณอยุทธ์ | I42: 0 | J42: 0 | K42: 64.1 | L42: =+I42*400+J42*100+K42 -> 64.1
A43: =+A42+1 -> 5 | B43: 19483 | C43: 511 | D43: 10 | E43: 4829 IV 3050-1 | F43: ต.หาดทรายรี อ.เมืองชุมพร จ.ชุมพร | G43: หาดทรายรี | H43: คุณณัฐวุฒิ-คุณจันทาภา-คุณอยุทธ์ | I43: 0 | J43: 0 | K43: 67.2 | L43: =+I43*400+J43*100+K43 -> 67.2
A44: =+A43+1 -> 6 | B44: 19484 | C44: 510 | D44: 11 | E44: 4829 IV 3050-1 | F44: ต.หาดทรายรี อ.เมืองชุมพร จ.ชุมพร | G44: หาดทรายรี | H44: คุณณัฐวุฒิ-คุณจันทาภา-คุณอยุทธ์ | I44: 0 | J44: 0 | K44: 69.7 | L44: =+I44*400+J44*100+K44 -> 69.7
A45: =+A44+1 -> 7 | B45: 19485 | C45: 509 | D45: 12 | E45: 4829 IV 3050-1 | F45: ต.หาดทรายรี อ.เมืองชุมพร จ.ชุมพร | G45: หาดทรายรี | H45: คุณณัฐวุฒิ-คุณจันทาภา-คุณอยุทธ์ | I45: 0 | J45: 0 | K45: 74.7 | L45: =+I45*400+J45*100+K45 -> 74.7
A46: =+A45+1 -> 8 | B46: 19486 | C46: 508 | D46: 13 | E46: 4829 IV 3050-1 | F46: ต.หาดทรายรี อ.เมืองชุมพร จ.ชุมพร | G46: หาดทรายรี | H46: คุณณัฐวุฒิ-คุณจันทาภา-คุณอยุทธ์ | I46: 0 | J46: 0 | K46: 80.4 | L46: =+I46*400+J46*100+K46 -> 80.4
A47: =+A46+1 -> 9 | B47: 19487 | C47: 507 | D47: 14 | E47: 4829 IV 3050-1 | F47: ต.หาดทรายรี อ.เมืองชุมพร จ.ชุมพร | G47: หาดทรายรี | H47: คุณณัฐวุฒิ-คุณจันทาภา-คุณอยุทธ์ | I47: 0 | J47: 0 | K47: 86.1 | L47: =+I47*400+J47*100+K47 -> 86.1
...

Sheet สรุป5-69
A1: ค่าเช่าประจำเดือนพฤษภาคม 2569
B3: ค่าเช่าเดือนพฤษภาคม 2569 | J3: =+'5-69'!E48 -> 304174 | L3: สรุปยอดเงินเข้าบัญชี
B4: บวก | L4: บัญชี น.ส.ภาวิณี Kbank 119-3-21759-8 | Q4: =+H26 -> 86620
D5: 1.ค่าเช่าค้างจ่าย ค่ายหลวง น.ส. ภิญญ์วิภา ตามิ ขายหมูกระทะ | H5: 4888 | L5: บัญชี คุณรุจิรา Kbank 119-3-21471-8 | Q5: =+J26 -> 72200
D6: 2.เงินประกัน บ้านตลิ่งชัน | H6: 26000 | L6: บัญชี คุณจรรยพรรศ SCB 611-281075-3 | Q6: =+L26 -> 102594
D7: 3.เงินประกัน ที่ดินค่ายหลวงร้านซักผ้า | H7: 50000 | J7: =SUM(H5:H7) -> 80888 | L7: บัญชี คุณภาวินี SCB 611-261071-1 | Q7: =+M26 -> 36288
B8: รวมรับเงิน | J8: =+J3+J7 -> 385062 | L8: ฝากเงินเข้าบัญชี คุณนภา BAY เลขที่บัญชี 080-9-00794-8 | Q8: =SUM(Q4:Q7) -> 297702 | R8: =+Q8-242877 -> 54825
B9: หัก | C9: ค่าเช่ารับล่วงหน้า | L9: บัญชี คุณนภา Kbank 144-2-79103-8 | Q9: =+F23 -> 27000
D10: บจ. ดีแทค ไตรเน็ต DTAC (บ้านโป่ง) | H10: -40000 | L10: รวมยอดเงินเข้าบัญชี | Q10: =SUM(Q8:Q9) -> 324702 | R10: =+Q10-Q23 -> 0
D11: นายทรงพล หมื่นแก้ว วัดโกสินาราย์ ท่าผา | H11: -6000
D12: นายสมปอง กระต่ายทอง บ่อทรายหนองสาหร่าย | H12: -400
D13: นางนัยณา สีดา บ่อทรายบ้านยาง | H13: -1500
D14: นางนัยณา สีดา บ่อทรายสระตาสัง | H14: -600
D15: ค่าเช่าค้างจ่าย ทาวน์เฮ้าท์เชียงใหม่ เลขที่ 107/11 | H15: -6500
D16: ค่าเช่าค้างจ่าย ค่ายหลวง น.ส. ภิญญ์วิภา ตามิ ขายหมูกระทะ | H16: -5360 | J16: =SUM(H10:H16) -> -60360
B17: รวมยอดเงินเข้าบัญชี | J17: =SUM(J8:J16) -> 324702
J18: =+J17-'5-69'!K48 -> 0
F19: รายละเอียดเงินเข้าบัญชี
F20: คุณนภา (ทันตกรรม ร.9) | H20: น.ส. ภาวิณี (เชียงใหม่) | J20: น.ส.รุจิรา (แยกข่วงสิงห์) | L20: น.ส.จรรยพรรศ (บ้านโป่ง) | M20: น.ส.ภาวินี (ซอยมายเฮาส์) | N20: ฝากเงินสด | Q20: รวม
F21: กสิกร 144-2-79103-8 | H21: กสิกร 119-3-21759-8 | J21: กสิกร 119-3-21471-8 | L21: SCB 611-281075-3 | M21: SCB 611-261071-1 | N21: เกิน (ขาด) | R21: =+Q23-'4-69'!K47 -> 61325
A22: ยอดยกมา | F22: 417117.71 | H22: 1029.31 | I22: 0 | J22: 521.62 | L22: 616.63 | M22: 539.43 | Q22: =+M22+L22+J22+H22+F22 -> 419824.7
A23: บวก รับเงินค่าเช่า | F23: =+'1-69'!L48 -> 27000 | H23: =+'5-69'!M48 -> 86620 | J23: =+'5-69'!N48 -> 72200 | L23: =+'5-69'!O48 -> 102594 | M23: =+'5-69'!P48 -> 36288 | Q23: =+M23+L23+J23+H23+F23 -> 324702
A24: บวก ดอกเบี้ยรับ | F24: 0 | H24: 0 | J24: 0 | Q24: =+F24+H24+J24+L24+M24 -> 0 | R24: =+Q26-'สรุป5-69'!Q8 -> 0
A25: รวมเงิน | F25: =SUM(F22:G24) -> 444117.71 | H25: =SUM(H22:I24) -> 87649.31 | J25: =SUM(J22:K24) -> 72721.62 | L25: =SUM(L22:L24) -> 103210.63 | M25: =SUM(M22:M24) -> 36827.43 | Q25: =SUM(F22:M22) -> 419824.7
A26: หัก ฝากเงินเข้าบัญชีคุณนภา Bay 080-9-00794-8 | H26: =+H23 -> 86620 | I26: =+I23 -> 0 | J26: =+J23 -> 72200 | L26: =+L23 -> 102594 | M26: =+M23 -> 36288 | Q26: =+M26+L26+J26+H26+O26 -> 297702 | R26: =+Q26-297702 -> 0
A27: ยอดคงเหลือในบัญชี วันที่ 22/05/2569 | F27: =+F25 -> 444117.71 | H27: =+H25-H26 -> 1029.31 | I27: =+I24 -> 0 | J27: =+J25-J26 -> 521.62 | L27: =+L25-L26 -> 616.63 | M27: =+M25-M26 -> 539.43 | Q27: =+M27+L27+J27+H27+F27 -> 446824.7
G29: =+F27-444117.71 -> 0 | H29: =+H27-1029.31 -> -2.2737368e-12 | J29: =+J27-521.62 -> -4.6611603e-12 | L29: =+L27-616.63 -> 4.6611603e-12 | M29: =+M27-539.43 -> 0

Sheet สรุป 4-69
A1: ค่าเช่าประจำเดือนเมษายน 2569
B3: ค่าเช่าเดือนเมษายน 2569 | J3: =+'4-69'!E47 -> 298965 | L3: สรุปยอดเงินเข้าบัญชี
B4: บวก | C4: ค่าเช่ารับล่วงหน้า | L4: บัญชี น.ส.ภาวิณี Kbank 119-3-21759-8 | Q4: =+H23 -> 93120
D5: 1.นายทรงพล หมื่นแก้ว วัดโกสินาราย์ ท่าผา | H5: 12000 | L5: บัญชี คุณรุจิรา Kbank 119-3-21471-8 | Q5: =+J23 -> 46200
D6: 2.นางนัยณา สีดา บ่อทรายบ้านยาง | H6: 3000 | L6: บัญชี คุณจรรยพรรศ SCB 611-281075-3 | Q6: =+L23 -> 71902
D7: 3.นางนัยณา สีดา บ่อทรายสระตาสัง | H7: 1200 | J7: =SUM(H5:H7) -> 16200 | L7: บัญชี คุณภาวินี SCB 611-261071-1 | Q7: =+M23 -> 31655
B8: รวมรับเงิน | J8: =+J7+J3 -> 315165 | L8: ฝากเงินเข้าบัญชี คุณนภา BAY เลขที่บัญชี 080-9-00794-8 | Q8: =SUM(Q4:Q7) -> 242877 | R8: =+Q8-242877 -> 0
B9: หัก | C9: ค่าเช่ารับล่วงหน้า | L9: บัญชี คุณนภา Kbank 144-2-79103-8 | Q9: =+F20 -> 27000
D10: บจ. ดีแทค ไตรเน็ต DTAC (บ้านโป่ง) | H10: -40000 | L10: รวมยอดเงินเข้าบัญชี | Q10: =SUM(Q8:Q9) -> 269877 | R10: =+Q10-Q20 -> 0
D11: นายสมปอง กระต่ายทอง บ่อทรายหนองสาหร่าย | H11: -400
D12: ค่าเช่าค้างจ่าย ค่ายหลวง น.ส. ภิญญ์วิภา ตามิ ขายหมูกระทะ | H12: -4888 | J12: =SUM(H10:H12) -> -45288
B13: รวมยอดเงินเข้าบัญชี | J13: =SUM(J8:J12) -> 269877
J14: =+J13-'4-69'!K47 -> 6500
F16: รายละเอียดเงินเข้าบัญชี
F17: คุณนภา (ทันตกรรม ร.9) | H17: น.ส. ภาวิณี (เชียงใหม่) | J17: น.ส.รุจิรา (แยกข่วงสิงห์) | L17: น.ส.จรรยพรรศ (บ้านโป่ง) | M17: น.ส.ภาวินี (ซอยมายเฮาส์) | N17: ฝากเงินสด | Q17: รวม
F18: กสิกร 144-2-79103-8 | H18: กสิกร 119-3-21759-8 | J18: กสิกร 119-3-21471-8 | L18: SCB 611-281075-3 | M18: SCB 611-261071-1 | N18: เกิน (ขาด)
A19: ยอดยกมา | F19: 390117.71 | H19: 1029.31 | I19: 0 | J19: 521.62 | L19: 616.63 | M19: 539.43 | Q19: =+M19+L19+J19+H19+F19 -> 392824.7
A20: บวก รับเงินค่าเช่า | F20: =+'1-69'!L48 -> 27000 | H20: =+'2-69'!M47 -> 93120 | J20: =+'2-69'!N47 -> 46200 | L20: =+'4-69'!O47 -> 71902 | M20: =+'4-69'!P47 -> 31655 | Q20: =+M20+L20+J20+H20+F20 -> 269877 | R20: =+Q20-'4-69'!K47 -> 6500
A21: บวก ดอกเบี้ยรับ | F21: 0 | H21: 0 | J21: 0 | Q21: =+F21+H21+J21+L21+M21 -> 0
A22: รวมเงิน | F22: =SUM(F19:G21) -> 417117.71 | H22: =SUM(H19:I21) -> 94149.31 | J22: =SUM(J19:K21) -> 46721.62 | L22: =SUM(L19:L21) -> 72518.63 | M22: =SUM(M19:M21) -> 32194.43 | Q22: =SUM(F21:M21) -> 0
A23: หัก ฝากเงินเข้าบัญชีคุณนภา Bay 080-9-00794-8 | H23: =+H20 -> 93120 | I23: =+I20 -> 0 | J23: =+J20 -> 46200 | L23: =+L20 -> 71902 | M23: =+M20 -> 31655 | Q23: =+M23+L23+J23+H23+O23 -> 242877 | R23: =+Q23-'สรุป 4-69'!Q8 -> 0
A24: ยอดคงเหลือในบัญชี วันที่ 24/04/2569 | F24: =+F22 -> 417117.71 | H24: =+H22-H23 -> 1029.31 | I24: =+I21 -> 0 | J24: =+J22-J23 -> 521.62 | L24: =+L22-L23 -> 616.63 | M24: =+M22-M23 -> 539.43 | Q24: =+M24+L24+J24+H24+F24 -> 419824.7
G26: =+F24-417117.71 -> 0 | H26: =+H24-1029.31 -> -2.2737368e-12 | J26: =+J24-521.62 -> 2.6147973e-12 | L26: =+L24-616.63 -> 4.6611603e-12 | M26: =+M24-539.43 -> 0

Sheet สรุป 3-69
A1: ค่าเช่าประจำเดือนมีนาคม 2569
B3: ค่าเช่าเดือนมีนาคม 2569 | J3: =+'3-69'!E47 -> 289077 | L3: สรุปยอดเงินเข้าบัญชี
B4: บวก | L4: บัญชี น.ส.ภาวิณี Kbank 119-3-21759-8 | Q4: =+H23 -> 93120
C5: ค่าเช่าค้างจ่าย ค่ายหลวง น.ส. ภิญญ์วิภา ตามิ ขายหมูกระทะ | J5: 4008 | L5: บัญชี คุณรุจิรา Kbank 119-3-21471-8 | Q5: =+J23 -> 46200
B6: รวมรับเงิน | J6: =SUM(J3:J5) -> 293085 | L6: บัญชี คุณจรรยพรรศ SCB 611-281075-3 | Q6: =+L23 -> 52794
B7: หัก | C7: ค่าเช่ารับล่วงหน้า | L7: บัญชี คุณภาวินี SCB 611-261071-1 | Q7: =+M23 -> 25471
D8: บจ. ดีแทค ไตรเน็ต DTAC (บ้านโป่ง) | H8: -40000 | L8: ฝากเงินเข้าบัญชี คุณนภา BAY เลขที่บัญชี 080-9-00794-8 | Q8: =SUM(Q4:Q7) -> 217585
D9: นายสมปอง กระต่ายทอง บ่อทรายหนองสาหร่าย | H9: -400 | L9: บัญชี คุณนภา Kbank 144-2-79103-8 | Q9: =+F20 -> 27000
D10: นางนัยณา สีดา บ่อทรายบ้านยาง | H10: -1500 | L10: รวมยอดเงินเข้าบัญชี | Q10: =SUM(Q8:Q9) -> 244585 | R10: =+Q10-Q20 -> 0
D11: นางนัยณา สีดา บ่อทรายสระตาสัง | H11: -600
D12: นายทรงพล หมื่นแก้ว วัดโกสินาราย์ ท่าผา | H12: -6000 | J12: =SUM(H8:H12) -> -48500
B13: รวมยอดเงินเข้าบัญชี | J13: =SUM(J6:J12) -> 244585
J14: =+J13-'3-69'!K47 -> 0
F16: รายละเอียดเงินเข้าบัญชี
F17: คุณนภา (ทันตกรรม ร.9) | H17: น.ส. ภาวิณี (เชียงใหม่) | J17: น.ส.รุจิรา (แยกข่วงสิงห์) | L17: น.ส.จรรยพรรศ (บ้านโป่ง) | M17: น.ส.ภาวินี (ซอยมายเฮาส์) | N17: ฝากเงินสด | Q17: รวม
F18: กสิกร 144-2-79103-8 | H18: กสิกร 119-3-21759-8 | J18: กสิกร 119-3-21471-8 | L18: SCB 611-281075-3 | M18: SCB 611-261071-1 | N18: เกิน (ขาด)
A19: ยอดยกมา | F19: 363117.71 | H19: 1029.31 | I19: 0 | J19: 521.62 | L19: 616.63 | M19: 539.43 | Q19: =+M19+L19+J19+H19+F19 -> 365824.7
A20: บวก รับเงินค่าเช่า | F20: =+'1-69'!L48 -> 27000 | H20: =+'2-69'!M47 -> 93120 | J20: =+'2-69'!N47 -> 46200 | L20: =+'3-69'!O47 -> 52794 | M20: =+'3-69'!P47 -> 25471 | Q20: =+M20+L20+J20+H20+F20 -> 244585 | R20: =+Q20-'3-69'!K47 -> 0
A21: บวก ดอกเบี้ยรับ | F21: 0 | H21: 0 | J21: 0 | Q21: =+F21+H21+J21+L21+M21 -> 0
A22: รวมเงิน | F22: =SUM(F19:G21) -> 390117.71 | H22: =SUM(H19:I21) -> 94149.31 | J22: =SUM(J19:K21) -> 46721.62 | L22: =SUM(L19:L21) -> 53410.63 | M22: =SUM(M19:M21) -> 26010.43 | Q22: =SUM(F21:M21) -> 0
A23: หัก ฝากเงินเข้าบัญชีคุณนภา Bay 080-9-00794-8 | H23: =+H20 -> 93120 | I23: =+I20 -> 0 | J23: =+J20 -> 46200 | L23: =+L20 -> 52794 | M23: =+M20 -> 25471 | Q23: =+M23+L23+J23+H23+O23 -> 217585 | R23: =+Q23-'สรุป 3-69'!Q8 -> 0
A24: ยอดคงเหลือในบัญชี วันที่ 23/03/2569 | F24: =+F22 -> 390117.71 | H24: =+H22-H23 -> 1029.31 | I24: =+I21 -> 0 | J24: =+J22-J23 -> 521.62 | L24: =+L22-L23 -> 616.63 | M24: =+M22-M23 -> 539.43 | Q24: =+M24+L24+J24+H24+F24 -> 392824.7
G26: =+F24-390117.71 -> 0 | H26: =+H24-1029.31 -> -2.2737368e-12 | J26: =+J24-521.62 -> 2.6147973e-12 | L26: =+L24-616.63 -> -2.6147973e-12 | M26: =+M24-539.43 -> 0

Sheet สรุป 2-69
A1: ค่าเช่าประจำเดือนกุมภาพันธ์ 2569
B3: ค่าเช่าเดือนกุมภาพันธ์ 2569 | J3: =+'2-69'!E47 -> 290365 | L3: สรุปยอดเงินเข้าบัญชี
B4: บวก | L4: บัญชี น.ส.ภาวิณี Kbank 119-3-21759-8 | Q4: =+H24 -> 93120
C5: อู่ซ่อมรถยนต์ เชียงใหม่ คุณสมชาย โอนเงินขาดเดือนม.ค. 69 | J5: 968 | L5: บัญชี คุณรุจิรา Kbank 119-3-21471-8 | Q5: =+J24 -> 46200
B6: รวมรับเงิน | J6: =SUM(J3:J5) -> 291333 | L6: บัญชี คุณจรรยพรรศ SCB 611-281075-3 | Q6: =+L24 -> 46586
B7: หัก | C7: ค่าเช่ารับล่วงหน้า | L7: บัญชี คุณภาวินี SCB 611-261071-1 | Q7: =+M24 -> 24951
D8: บจ. ดีแทค ไตรเน็ต DTAC (บ้านโป่ง) | H8: -40000 | L8: ฝากเงินเข้าบัญชี คุณนภา BAY เลขที่บัญชี 080-9-00794-8 | Q8: =SUM(Q4:Q7) -> 210857
D9: นายสมปอง กระต่ายทอง บ่อทรายหนองสาหร่าย | H9: -400 | L9: บัญชี คุณนภา Kbank 144-2-79103-8 | Q9: =+F21 -> 27000
D10: นางนัยณา สีดา บ่อทรายบ้านยาง | H10: -1500 | L10: รวมยอดเงินเข้าบัญชี | Q10: =SUM(Q8:Q9) -> 237857 | R10: =+Q10-Q21 -> 0
D11: นางนัยณา สีดา บ่อทรายสระตาสัง | H11: -600
D12: นายทรงพล หมื่นแก้ว วัดโกสินาราย์ ท่าผา | H12: -6000
D13: ค่าเช่าค้างจ่าย ค่ายหลวง น.ส. ภิญญ์วิภา ตามิ ขายหมูกระทะ | H13: -4008 | J13: =SUM(H8:H13) -> -52508
B14: รวมยอดเงินเข้าบัญชี | J14: =+J6+J13 -> 238825
J15: =+'2-69'!K47-J14 -> -968
F17: รายละเอียดเงินเข้าบัญชี
F18: คุณนภา (ทันตกรรม ร.9) | H18: น.ส. ภาวิณี (เชียงใหม่) | J18: น.ส.รุจิรา (แยกข่วงสิงห์) | L18: น.ส.จรรยพรรศ (บ้านโป่ง) | M18: น.ส.ภาวินี (ซอยมายเฮาส์) | N18: ฝากเงินสด | Q18: รวม
F19: กสิกร 144-2-79103-8 | H19: กสิกร 119-3-21759-8 | J19: กสิกร 119-3-21471-8 | L19: SCB 611-281075-3 | M19: SCB 611-261071-1 | N19: เกิน (ขาด)
A20: ยอดยกมา | F20: 317092.62 | H20: 1029.31 | I20: 0 | J20: 521.62 | L20: 616.63 | M20: 539.43 | Q20: =+M20+L20+J20+H20+F20 -> 319799.61
A21: บวก รับเงินค่าเช่า | F21: =+'1-69'!L48 -> 27000 | H21: =+'2-69'!M47 -> 93120 | J21: =+'2-69'!N47 -> 46200 | L21: =+'2-69'!O47 -> 46586 | M21: =+'2-69'!P47 -> 24951 | Q21: =+M21+L21+J21+H21+F21 -> 237857 | R21: =+Q21-'2-69'!K47 -> 0
A22: บวก ดอกเบี้ยรับ | F22: 0 | H22: 0 | J22: 0 | Q22: =+F22+H22+J22+L22+M22 -> 0
A23: รวมเงิน | F23: =SUM(F20:G22) -> 344092.62 | H23: =SUM(H20:I22) -> 94149.31 | J23: =SUM(J20:K22) -> 46721.62 | L23: =SUM(L20:L22) -> 47202.63 | M23: =SUM(M20:M22) -> 25490.43 | Q23: =SUM(F22:M22) -> 0
A24: หัก ฝากเงินเข้าบัญชีคุณนภา Bay 080-9-00794-8 | H24: =+H21 -> 93120 | I24: =+I21 -> 0 | J24: =+J21 -> 46200 | L24: =+L21 -> 46586 | M24: =+M21 -> 24951 | Q24: =+M24+L24+J24+H24+O24 -> 210857 | R24: =+Q24-'สรุป 2-69'!Q8 -> 0
A25: ยอดคงเหลือในบัญชี วันที่ 24/02/2569 | F25: =+F23 -> 344092.62 | H25: =+H23-H24 -> 1029.31 | I25: =+I22 -> 0 | J25: =+J23-J24 -> 521.62 | L25: =+L23-L24 -> 616.63 | M25: =+M23-M24 -> 539.43 | Q25: =+M25+L25+J25+H25+F25 -> 346799.61
G27: =+F25-344092.62 -> 0 | H27: =+H25-1029.31 -> -2.2737368e-12 | J27: =+J25-521.62 -> 2.6147973e-12 | L27: =+L25-616.63 -> -2.6147973e-12 | M27: =+M25-539.43 -> 0

Sheet สรุป 1-69
A1: ค่าเช่าประจำเดือนมกราคม 2569
B3: ค่าเช่าเดือนมกราคม 2569 | J3: =+'1-69'!E48 -> 291739 | L3: สรุปยอดเงินเข้าบัญชี
B4: บวก | L4: บัญชี น.ส.ภาวิณี Kbank 119-3-21759-8 | Q4: =+H24 -> 92152
C5: ค่าเช่าค้างจ่าย เดือนธ.ค. 68 ค่ายหลวง น.ส. ภิญญ์วิภา ตามิ ขายหมูกระทะ | H5: 5072 | L5: บัญชี คุณรุจิรา Kbank 119-3-21471-8 | Q5: =+J24 -> 46200
C6: ค่าเช่ารับล่วงหน้า | L6: บัญชี คุณจรรยพรรศ SCB 611-281075-3 | Q6: =+L24 -> 87374
D7: 1.นายทรงพล หมื่นแก้ว วัดโกสินาราย์ ท่าผา | H7: 12000 | L7: บัญชี คุณภาวินี SCB 611-261071-1 | Q7: =+M24 -> 23717
D8: 2.นางนัยณา สีดา บ่อทรายบ้านยาง | H8: 3000 | L8: ฝากเงินเข้าบัญชี คุณนภา BAY เลขที่บัญชี 080-9-00794-8 | Q8: =SUM(Q4:Q7) -> 249443
D9: 3.นางนัยณา สีดา บ่อทรายสระตาสัง | H9: 1200 | L9: บัญชี คุณนภา Kbank 144-2-79103-8 | Q9: =+F21 -> 27000
D10: 4.นายสมปอง กระต่ายทอง บ่อทรายหน่องสาหร่าย | H10: 4400 | J10: =SUM(H5:H10) -> 25672 | L10: รวมยอดเงินเข้าบัญชี | Q10: =SUM(Q8:Q9) -> 276443 | R10: =+Q10-Q21 -> 0
B11: หัก | C11: ค่าเช่ารับล่วงหน้า
D12: บจ. ดีแทค ไตรเน็ต DTAC (บ้านโป่ง) | H12: -40000
D13: อู่ซ่อมรถยนต์ เชียงใหม่ คุณสมชาย โอนเงินขาด | H13: -968 | J13: =SUM(H12:H13) -> -40968
B14: รวมยอดเงินเข้าบัญชี | J14: =SUM(J3:J13) -> 276443
J15: =+J14-'1-69'!K48 -> 0
F17: รายละเอียดเงินเข้าบัญชี
F18: คุณนภา (ทันตกรรม ร.9) | H18: น.ส. ภาวิณี (เชียงใหม่) | J18: น.ส.รุจิรา (แยกข่วงสิงห์) | L18: น.ส.จรรยพรรศ (บ้านโป่ง) | M18: น.ส.ภาวินี (ซอยมายเฮาส์) | N18: ฝากเงินสด | Q18: รวม
F19: กสิกร 144-2-79103-8 | H19: กสิกร 119-3-21759-8 | J19: กสิกร 119-3-21471-8 | L19: SCB 611-281075-3 | M19: SCB 611-261071-1 | N19: เกิน (ขาด)
A20: ยอดยกมา | F20: 290092.62 | H20: 1029.31 | I20: 0 | J20: 521.62 | L20: 576.68 | M20: 519.6 | Q20: =+M20+L20+J20+H20+F20 -> 292739.83
A21: บวก รับเงินค่าเช่า | F21: =+'1-69'!L48 -> 27000 | H21: =+'1-69'!M48 -> 92152 | J21: =+'1-69'!N48 -> 46200 | L21: =+'1-69'!O48 -> 87374 | M21: =+'1-69'!P48 -> 23717 | Q21: =+M21+L21+J21+H21+F21 -> 276443 | R21: =+Q21-'1-69'!K48 -> 0
A22: บวก ดอกเบี้ยรับ | F22: 0 | H22: 0 | J22: 0 | L22: 39.95 | M22: 19.83 | Q22: =+F22+H22+J22+L22+M22 -> 59.78
A23: รวมเงิน | F23: =SUM(F20:G22) -> 317092.62 | H23: =SUM(H20:I22) -> 93181.31 | J23: =SUM(J20:K22) -> 46721.62 | L23: =SUM(L20:L22) -> 87990.63 | M23: =SUM(M20:M22) -> 24256.43 | Q23: =SUM(F22:M22) -> 59.78
A24: หัก ฝากเงินเข้าบัญชีคุณนภา Bay 080-9-00794-8 | H24: =+H21 -> 92152 | I24: =+I21 -> 0 | J24: =+J21 -> 46200 | L24: =+L21 -> 87374 | M24: =+M21 -> 23717 | Q24: =+M24+L24+J24+H24+O24 -> 249443 | R24: =+Q24-'สรุป 1-69'!Q8 -> 0
A25: ยอดคงเหลือในบัญชี 26/01/2569 | F25: =+F23 -> 317092.62 | H25: =+H23-H24 -> 1029.31 | I25: =+I22 -> 0 | J25: =+J23-J24 -> 521.62 | L25: =+L23-L24 -> 616.63 | M25: =+M23-M24 -> 539.43 | Q25: =+M25+L25+J25+H25+F25 -> 319799.61
G27: =+F25-317092.62 -> 0 | H27: =+H25-1029.31 -> -2.2737368e-12 | J27: =+J25-521.62 -> 2.6147973e-12 | L27: =+L25-616.63 -> 4.6611603e-12 | M27: =+M25-539.43 -> 0

Sheet 5-69
A1: รายละเอียดค่าเช่า
A2: ประจำเดือนพฤษภาคม 2569
A4: ที่ | B4: รับเงินจาก | C4: สถานที่ | E4: รายรับ | L4: คุณนภา | M4: น.ส.ภาวิณี วังมะนาว | N4: คุณรุจิรา เกตุสถิตย์ | O4: คุณจรรยพรรศ จันทร์เครือ | P4: คุณภาวินี จอมพล
E5: ค่าเช่า | F5: บวก เงินประกัน | G5: บวก ค่าเช่าค้างจ่าย | H5: ค่าเช่ารับล่วงหน้า | I5: บวก เงินประกัน | J5: หัก ค้างจ่าย | K5: ยอดเงินเข้าบัญชี | L5: กสิกร 144-2-79103-8 | M5: กสิกร 119-3-21759-8 | N5: กสิกร 119-3-21471-8 | O5: SCB 611-281075-3 | P5: SCB 611-261071-1
A6: 1 | B6: คุณจินดา โกพลรัตน์ (ผู้เช่าใหม่) | C6: ทาวน์เฮ้าท์เชียงใหม่ เลขที่ 107/11 | E6: 6500 | J6: -6500 | M6: ค้างจ่าย
A7: 2 | B7: คุณกมลวรรณ กลอนกลาง | C7: แยกข่วงสิงห์ เชียงใหม่ | E7: 46200 | K7: =SUM(E7:J7) -> 46200 | N7: 46200
A8: =+A7+1 -> 3 | B8: นายสมชัย พาราสรรเสริญ | C8: อู่ซ่อมรถยนต์ เชียงใหม่ | E8: 10648 | K8: =SUM(E8:J8) -> 10648 | M8: =+K8 -> 10648
A9: =+A8+1 -> 4 | B9: นางอารี อุ่นแสง | C9: ที่จอดรถ เชียงใหม่ | E9: 7986 | K9: =SUM(E9:J9) -> 7986 | M9: =+K9 -> 7986
A10: =+A9+1 -> 5 | B10: นายสิริชัย นครสิงห์ | C10: ทาวน์เฮ้าท์ เชียงใหม่ เลขที่ 107/12 | E10: 7986 | K10: =SUM(E10:J10) -> 7986 | M10: =+K10 -> 7986
A11: =+A10+1 -> 6 | B11: น.ส.นวรัตน์ เกตตะพันธุ์ (คุณปิติ) | C11: SN อพาร์ทเม้นท์ ชั้นที่ 1 | E11: 60000 | K11: =SUM(E11:J11) -> 60000 | M11: =+K11 -> 60000
A12: เชียงใหม่ | E12: =SUM(E6:E11) -> 139320 | F12: =SUM(F6:F11) -> 0 | G12: =SUM(G6:G11) -> 0 | H12: =SUM(H6:H11) -> 0 | I12: =SUM(I6:I11) -> 0 | J12: =SUM(J6:J11) -> -6500 | K12: =SUM(K6:K11) -> 132820 | L12: =SUM(L6:L11) -> 0 | ... P12: =SUM(P6:P11) -> 0
A13: =+A11+1 -> 7 | B13: บริษัท สมบุญ พัฒนา จำกัด | C13: บ้านตลิ่งชัน | I13: 26000 | K13: =SUM(E13:J13) -> 26000 | N13: 26000
A14: กรุงเทพมหานคร | E14: =SUM(E13) -> 0 | F14: =+F13 -> 0 | G14: =SUM(G13) -> 0 | H14: =+H13 -> 0 | I14: =+I13 -> 26000 | J14: =SUM(J13) -> 0 | K14: =SUM(K13) -> 26000 | L14: =SUM(L13) -> 0 | M14: =SUM(M13) -> 0 | N14: =SUM(N13) -> 26000 | O14: =SUM(O13) -> 0 | P14: =SUM(P13) -> 0
A15: =+A13+1 -> 8 | B15: ซอยมายเฮาส์ ห้อง BP35/533 | C15: ห้องเช่าซอยมายเฮาส์ | E15: 2895 | K15: =+E15+J15 -> 2895 | P15: =+K15 -> 2895
A16: =+A15+1 -> 9 | B16: ซอยมายเฮาส์ ห้อง BP35/534 | C16: ห้องเช่าซอยมายเฮาส์ | E16: 1651 | K16: =SUM(E16:J16) -> 1651 | P16: =+K16 -> 1651
A17: =+A16+1 -> 10 | B17: ซอยมายเฮาส์ ห้อง BP35/535 | C17: ห้องเช่าซอยมายเฮาส์ | E17: 2267 | K17: =+E17 -> 2267 | P17: =+K17 -> 2267
A18: =+A17+1 -> 11 | B18: ซอยมายเฮาส์ ห้อง BP35/536 | C18: ห้องเช่าซอยมายเฮาส์ | E18: 6615 | J18: 0 | K18: =+E18+F18 -> 6615 | P18: =+K18 -> 6615
A19: =+A18+1 -> 12 | B19: ซอยมายเฮาส์ ห้อง BP35/537 | C19: ห้องเช่าซอยมายเฮาส์ | E19: 2033 | K19: =SUM(E19:J19) -> 2033 | P19: =+K19 -> 2033
A20: =+A19+1 -> 13 | B20: ซอยมายเฮาส์ ห้อง BP35/538 | C20: ห้องเช่าซอยมายเฮาส์ | E20: ห้องว่าง | P20: =+K20 -> 0
A21: =+A20+1 -> 14 | B21: ซอยมายเฮาส์ ห้อง BP35/539 | C21: ห้องเช่าซอยมายเฮาส์ | E21: 1525 | K21: =+E21 -> 1525 | P21: =+K21 -> 1525
A22: =+A21+1 -> 15 | B22: ซอยมายเฮาส์ ห้อง BP35/540 | C22: ห้องเช่าซอยมายเฮาส์ | E22: 1619 | K22: =+E22 -> 1619 | P22: =+K22 -> 1619
A23: =+A22+1 -> 16 | B23: ซอยมายเฮาส์ ห้อง BP35/541 | C23: ห้องเช่าซอยมายเฮาส์ | E23: 3900 | K23: =+E23+I23 -> 3900 | P23: =+K23 -> 3900
A24: =+A23+1 -> 17 | B24: ซอยมายเฮาส์ ห้อง BP35/542 | C24: ห้องเช่าซอยมายเฮาส์ | E24: 1977 | K24: =+E24 -> 1977 | P24: =+K24 -> 1977
A25: =+A24+1 -> 18 | B25: ซอยมายเฮาส์ ห้อง BP35/543 | C25: ห้องเช่าซอยมายเฮาส์ | E25: 1673 | K25: =+E25 -> 1673 | P25: =+K25 -> 1673
A26: =+A25+1 -> 19 | B26: ซอยมายเฮาส์ ห้อง BP35/544 | C26: ห้องเช่าซอยมายเฮาส์ | E26: 2045 | K26: =+E26 -> 2045 | P26: =+K26 -> 2045
A27: =+A26+1 -> 20 | B27: ซอยมายเฮาส์ ห้อง BP35/545 | C27: ห้องเช่าซอยมายเฮาส์ | E27: 2613 | K27: =+E27 -> 2613 | P27: =+K27 -> 2613
A28: =+A27+1 -> 21 | B28: ซอยมายเฮาส์ ห้อง BP35/546 | C28: ห้องเช่าซอยมายเฮาส์ | E28: 1599 | K28: =+E28 -> 1599 | P28: =+K28 -> 1599
A29: =+A28+1 -> 22 | B29: ซอยมายเฮาส์ ห้อง BP35/547 | C29: ห้องเช่าซอยมายเฮาส์ | E29: 2065 | K29: =+J29+E29 -> 2065 | P29: =+K29 -> 2065
A30: =+A29+1 -> 23 | B30: ซอยมายเฮาส์ ห้อง BP35/548 | C30: ห้องเช่าซอยมายเฮาส์ | E30: 1811 | K30: =+E30 -> 1811 | P30: =+K30 -> 1811
A31: ซอยมายเฮาส์ 16 ห้อง | E31: =SUM(E15:E30) -> 36288 | F31: =SUM(F15:F30) -> 0 | G31: =SUM(G15:G30) -> 0 | H31: =SUM(H15:H30) -> 0 | J31: =SUM(J15:J30) -> 0 | K31: =SUM(K15:K30) -> 36288 | L31: =SUM(L15:L30) -> 0 | M31: =SUM(M15:M30) -> 0 | N31: =SUM(N15:N30) -> 0 | O31: =SUM(O15:O30) -> 0 | P31: =SUM(P15:P30) -> 36288
A32: =+A30+1 -> 24 | B32: อาคารพาณิชย์ ร. 9 คลินิกบ้านเลขที่ 28/7 | C32: คลินิกทันตกรรม อาคารพาณิชย์ ร.9 | E32: 27000 | K32: =SUM(E32:J32) -> 27000 | L32: 27000
A33: =+A32+1 -> 25 | B33: บจ. ดีแทค ไตรเน็ต เช่าในนามภาวิณี วังมะนาว | C33: DTAC (บ้านโป่ง) | E33: 40000 | H33: -40000 | K33: =SUM(E33:J33) -> 0 | M33: ค่าเช่ารับล่วงหน้า
A34: =+A33+1 -> 26 | B34: บ้านว่าง | C34: 190/60 หมู่ 4 ต. เบิกไพร อ. ต้อย | K34: =SUM(E34:J34) -> 0
A35: =+A34+1 -> 27 | B35: นายศิรภพ วิยาภรณ์ (ร้านนวด) | C35: บ้านตลาด 143-145 | E35: 18150 | K35: =SUM(E35:J35) -> 18150 | O35: =+K35 -> 18150
A36: =+A35+1 -> 28 | B36: นางอุษา ตันติไชยากุล | C36: บ้านท.3 401/1 ถนนทรงพล | E36: 5324 | K36: =SUM(E36:J36) -> 5324 | O36: =+K36 -> 5324
A37: =+A36+1 -> 29 | B37: น.ส.อาพร กลัดกลิ่น | C37: บ้านท.3 401/2 ถนนทรงพล | E37: 5324 | K37: =SUM(E37:J37) -> 5324 | O37: =+K37 -> 5324
A38: =+A37+1 -> 30 | B38: น.ส. เพียงตวัน อารีย์ ขายก๋วยเตี๋ยว | C38: ค่ายหลวง | E38: 3800 | K38: =SUM(E38:J38) -> 3800 | O38: 3800
A39: =+A38+1 -> 31 | B39: นายวรพล แม้นจิตต์ ขายน้ำกระท่อม | C39: ค่ายหลวง | E39: 7380 | K39: =SUM(E39:J39) -> 7380 | O39: =+K39 -> 7380
A40: =+A39+1 -> 32 | B40: น.ส. ภิญญ์วิภา ตามิ ขายหมูกระทะ | C40: ค่ายหลวง | E40: 5360 | G40: 4888 | J40: -5360 | K40: =+E40+G40+J40 -> 4888 | O40: =+K40 -> 4888
A41: =+A40+1 -> 33 | B41: น.ส. ธิดารัตน์ ตันชัยสวัสดิ์ ขายเบอร์เกอร์รี่ | C41: ค่ายหลวง | E41: 7728 | K41: =SUM(E41:J41) -> 7728 | O41: =+K41 -> 7728
...

Sheet 4-69
A1: รายละเอียดค่าเช่า
A2: ประจำเดือนเมษายน 2569
A4: ที่ | B4: รับเงินจาก | C4: สถานที่ | E4: รายรับ | L4: คุณนภา | M4: น.ส.ภาวิณี วังมะนาว | N4: คุณรุจิรา เกตุสถิตย์ | O4: คุณจรรยพรรศ จันทร์เครือ | P4: คุณภาวินี จอมพล
E5: ค่าเช่า | F5: บวก เงินประกัน | G5: บวก ค่าเช่าค้างจ่าย | H5: ค่าเช่ารับล่วงหน้า | I5: หัก ภาษี ณ ที่จ่าย | J5: หัก เงิน(ขาด)เกิน | K5: ยอดเงินเข้าบัญชี | L5: กสิกร 144-2-79103-8 | M5: กสิกร 119-3-21759-8 | N5: กสิกร 119-3-21471-8 | O5: SCB 611-281075-3 | P5: SCB 611-261071-1
A6: 1 | B6: คุณจินดา โกพลรัตน์ (ผู้เช่าใหม่) | C6: ทาวน์เฮ้าท์เชียงใหม่ เลขที่ 107/11 | E6: 6500 | M6: ค้างจ่าย
A7: 2 | B7: คุณกมลวรรณ กลอนกลาง | C7: แยกข่วงสิงห์ เชียงใหม่ | E7: 46200 | K7: =SUM(E7:J7) -> 46200 | N7: 46200
A8: =+A7+1 -> 3 | B8: นายสมชัย พาราสรรเสริญ | C8: อู่ซ่อมรถยนต์ เชียงใหม่ | E8: 10648 | K8: =SUM(E8:J8) -> 10648 | M8: =+K8 -> 10648
A9: =+A8+1 -> 4 | B9: นางอารี อุ่นแสง | C9: ที่จอดรถ เชียงใหม่ | E9: 7986 | K9: =SUM(E9:J9) -> 7986 | M9: =+K9 -> 7986
A10: =+A9+1 -> 5 | B10: นายสิริชัย นครสิงห์ | C10: ทาวน์เฮ้าท์ เชียงใหม่ เลขที่ 107/12 | E10: 7986 | K10: =SUM(E10:J10) -> 7986 | M10: =+K10 -> 7986
A11: =+A10+1 -> 6 | B11: น.ส.นวรัตน์ เกตตะพันธุ์ (คุณปิติ) | C11: SN อพาร์ทเม้นท์ ชั้นที่ 1 | E11: 60000 | K11: =SUM(E11:J11) -> 60000 | M11: =+K11 -> 60000
A12: เชียงใหม่ | E12: =SUM(E6:E11) -> 139320 | F12: =SUM(F6:F11) -> 0 | G12: =SUM(G6:G11) -> 0 | H12: =SUM(H6:H11) -> 0 | I12: =SUM(I6:I11) -> 0 | J12: =SUM(J6:J11) -> 0 | K12: =SUM(K6:K11) -> 132820 | L12: =SUM(L6:L11) -> 0 | ... P12: =SUM(P6:P11) -> 0
A13: =+A11+1 -> 7 | B13: ห้องว่าง | C13: บ้านตลิ่งชัน | K13: =SUM(E13:J13) -> 0
A14: กรุงเทพมหานคร | E14: =SUM(E13) -> 0 | F14: =+F13 -> 0 | G14: =SUM(G13) -> 0 | H14: =+H13 -> 0 | I14: =+I13 -> 0 | J14: =SUM(J13) -> 0 | K14: =SUM(K13) -> 0 | L14: =SUM(L13) -> 0 | M14: =SUM(M13) -> 0 | N14: =SUM(N13) -> 0 | O14: =SUM(O13) -> 0 | P14: =SUM(P13) -> 0
A15: =+A13+1 -> 8 | B15: ซอยมายเฮาส์ ห้อง BP35/533 | C15: ห้องเช่าซอยมายเฮาส์ | E15: 2307 | K15: =+E15+J15 -> 2307 | P15: =+K15 -> 2307
A16: =+A15+1 -> 9 | B16: ซอยมายเฮาส์ ห้อง BP35/534 | C16: ห้องเช่าซอยมายเฮาส์ | E16: 1675 | K16: =SUM(E16:J16) -> 1675 | P16: =+K16 -> 1675
A17: =+A16+1 -> 10 | B17: ซอยมายเฮาส์ ห้อง BP35/535 | C17: ห้องเช่าซอยมายเฮาส์ | E17: 1927 | K17: =+E17 -> 1927 | P17: =+K17 -> 1927
A18: =+A17+1 -> 11 | B18: ซอยมายเฮาส์ ห้อง BP35/536 | C18: ห้องเช่าซอยมายเฮาส์ | E18: 5383 | J18: 0 | K18: =+E18+F18 -> 5383 | P18: =+K18 -> 5383
A19: =+A18+1 -> 12 | B19: ซอยมายเฮาส์ ห้อง BP35/537 | C19: ห้องเช่าซอยมายเฮาส์ | E19: 2067 | K19: =SUM(E19:J19) -> 2067 | P19: =+K19 -> 2067
A20: =+A19+1 -> 13 | B20: ซอยมายเฮาส์ ห้อง BP35/538 | C20: ห้องเช่าซอยมายเฮาส์ | E20: ห้องว่าง | P20: =+K20 -> 0
A21: =+A20+1 -> 14 | B21: ซอยมายเฮาส์ ห้อง BP35/539 | C21: ห้องเช่าซอยมายเฮาส์ | E21: 1417 | K21: =+E21 -> 1417 | P21: =+K21 -> 1417
A22: =+A21+1 -> 15 | B22: ซอยมายเฮาส์ ห้อง BP35/540 | C22: ห้องเช่าซอยมายเฮาส์ | E22: 1813 | K22: =+E22 -> 1813 | P22: =+K22 -> 1813
A23: =+A22+1 -> 16 | B23: ซอยมายเฮาส์ ห้อง BP35/541 | C23: ห้องเช่าซอยมายเฮาส์ | E23: ห้องว่าง
A24: =+A23+1 -> 17 | B24: ซอยมายเฮาส์ ห้อง BP35/542 | C24: ห้องเช่าซอยมายเฮาส์ | E24: 3900 | K24: =+E24 -> 3900 | P24: =+K24 -> 3900
A25: =+A24+1 -> 18 | B25: ซอยมายเฮาส์ ห้อง BP35/543 | C25: ห้องเช่าซอยมายเฮาส์ | E25: 1635 | K25: =+E25 -> 1635 | P25: =+K25 -> 1635
A26: =+A25+1 -> 19 | B26: ซอยมายเฮาส์ ห้อง BP35/544 | C26: ห้องเช่าซอยมายเฮาส์ | E26: 1831 | K26: =+E26 -> 1831 | P26: =+K26 -> 1831
A27: =+A26+1 -> 20 | B27: ซอยมายเฮาส์ ห้อง BP35/545 | C27: ห้องเช่าซอยมายเฮาส์ | E27: 2309 | K27: =+E27 -> 2309 | P27: =+K27 -> 2309
A28: =+A27+1 -> 21 | B28: ซอยมายเฮาส์ ห้อง BP35/546 | C28: ห้องเช่าซอยมายเฮาส์ | E28: 1687 | K28: =+E28 -> 1687 | P28: =+K28 -> 1687
A29: =+A28+1 -> 22 | B29: ซอยมายเฮาส์ ห้อง BP35/547 | C29: ห้องเช่าซอยมายเฮาส์ | E29: 1957 | K29: =+J29+E29 -> 1957 | P29: =+K29 -> 1957
A30: =+A29+1 -> 23 | B30: ซอยมายเฮาส์ ห้อง BP35/548 | C30: ห้องเช่าซอยมายเฮาส์ | E30: 1747 | K30: =+E30 -> 1747 | P30: =+K30 -> 1747
A31: ซอยมายเฮาส์ 16 ห้อง | E31: =SUM(E15:E30) -> 31655 | F31: =SUM(F15:F30) -> 0 | G31: =SUM(G15:G30) -> 0 | H31: =SUM(H15:H30) -> 0 | J31: =SUM(J15:J30) -> 0 | K31: =SUM(K15:K30) -> 31655 | L31: =SUM(L15:L30) -> 0 | M31: =SUM(M15:M30) -> 0 | N31: =SUM(N15:N30) -> 0 | O31: =SUM(O15:O30) -> 0 | P31: =SUM(P15:P30) -> 31655
A32: =+A30+1 -> 24 | B32: อาคารพาณิชย์ ร. 9 คลินิกบ้านเลขที่ 28/7 | C32: คลินิกทันตกรรม อาคารพาณิชย์ ร.9 | E32: 27000 | K32: =SUM(E32:J32) -> 27000 | L32: 27000
A33: =+A32+1 -> 25 | B33: บจ. ดีแทค ไตรเน็ต เช่าในนามภาวิณี วังมะนาว | C33: DTAC (บ้านโป่ง) | E33: 40000 | H33: -40000 | K33: =SUM(E33:J33) -> 0 | M33: ค่าเช่ารับล่วงหน้า
A34: =+A33+1 -> 26 | B34: บ้านว่าง | C34: 190/60 หมู่ 4 ต. เบิกไพร อ. ต้อย | K34: =SUM(E34:J34) -> 0
A35: =+A34+1 -> 27 | B35: นายศิรภพ วิยาภรณ์ (ร้านนวด) | C35: บ้านตลาด 143-145 | E35: 18150 | K35: =SUM(E35:J35) -> 18150 | O35: =+K35 -> 18150
A36: =+A35+1 -> 28 | B36: นางอุษา ตันติไชยากุล | C36: บ้านท.3 401/1 ถนนทรงพล | E36: 5324 | K36: =SUM(E36:J36) -> 5324 | O36: =+K36 -> 5324
A37: =+A36+1 -> 29 | B37: น.ส.อาพร กลัดกลิ่น | C37: บ้านท.3 401/2 ถนนทรงพล | E37: 5324 | K37: =SUM(E37:J37) -> 5324 | O37: =+K37 -> 5324
A38: =+A37+1 -> 30 | B38: น.ส. เพียงตวัน อารีย์ ขายก๋วยเตี๋ยว | C38: ค่ายหลวง | E38: 3800 | K38: =SUM(E38:J38) -> 3800 | O38: 3800
A39: =+A38+1 -> 31 | B39: นายวรพล แม้นจิตต์ ขายน้ำกระท่อม | C39: ค่ายหลวง | E39: 7548 | K39: =SUM(E39:J39) -> 7548 | O39: =+K39 -> 7548
A40: =+A39+1 -> 32 | B40: น.ส. ภิญญ์วิภา ตามิ ขายหมูกระทะ | C40: ค่ายหลวง | E40: 4888 | K40: 0 | O40: ค้างจ่าย
A41: =+A40+1 -> 33 | B41: น.ส. ธิดารัตน์ ตันชัยสวัสดิ์ ขายเบอร์เกอร์รี่ | C41: ค่ายหลวง | E41: 7456 | K41: =SUM(E41:J41) -> 7456 | O41: =+K41 -> 7456
...

Sheet 3-69
A1: รายละเอียดค่าเช่า
A2: ประจำเดือนมีนาคม 2569
A4: ที่ | B4: รับเงินจาก | C4: สถานที่ | E4: รายรับ | L4: คุณนภา | M4: น.ส.ภาวิณี วังมะนาว | N4: คุณรุจิรา เกตุสถิตย์ | O4: คุณจรรยพรรศ จันทร์เครือ | P4: คุณภาวินี จอมพล
E5: ค่าเช่า | F5: บวก เงินประกัน | G5: บวก ค่าเช่าค้างจ่าย | H5: ค่าเช่ารับล่วงหน้า | I5: หัก ภาษี ณ ที่จ่าย | J5: หัก เงิน(ขาด)เกิน | K5: ยอดเงินเข้าบัญชี | L5: กสิกร 144-2-79103-8 | M5: กสิกร 119-3-21759-8 | N5: กสิกร 119-3-21471-8 | O5: SCB 611-281075-3 | P5: SCB 611-261071-1
A6: 1 | B6: คุณจินดา โกพลรัตน์ (ผู้เช่าใหม่) | C6: ทาวน์เฮ้าท์เชียงใหม่ เลขที่ 107/11 | E6: 6500 | K6: =SUM(E6:J6) -> 6500 | M6: 6500
A7: 2 | B7: คุณกมลวรรณ กลอนกลาง | C7: แยกข่วงสิงห์ เชียงใหม่ | E7: 46200 | K7: =SUM(E7:J7) -> 46200 | N7: 46200
A8: =+A7+1 -> 3 | B8: นายสมชัย พาราสรรเสริญ | C8: อู่ซ่อมรถยนต์ เชียงใหม่ | E8: 10648 | K8: =SUM(E8:J8) -> 10648 | M8: =+K8 -> 10648
A9: =+A8+1 -> 4 | B9: นางอารี อุ่นแสง | C9: ที่จอดรถ เชียงใหม่ | E9: 7986 | K9: =SUM(E9:J9) -> 7986 | M9: =+K9 -> 7986
A10: =+A9+1 -> 5 | B10: นายสิริชัย นครสิงห์ | C10: ทาวน์เฮ้าท์ เชียงใหม่ เลขที่ 107/12 | E10: 7986 | K10: =SUM(E10:J10) -> 7986 | M10: =+K10 -> 7986
A11: =+A10+1 -> 6 | B11: น.ส.นวรัตน์ เกตตะพันธุ์ (คุณปิติ) | C11: SN อพาร์ทเม้นท์ ชั้นที่ 1 | E11: 60000 | K11: =SUM(E11:J11) -> 60000 | M11: =+K11 -> 60000
A12: เชียงใหม่ | E12: =SUM(E6:E11) -> 139320 | F12: =SUM(F6:F11) -> 0 | G12: =SUM(G6:G11) -> 0 | H12: =SUM(H6:H11) -> 0 | I12: =SUM(I6:I11) -> 0 | J12: =SUM(J6:J11) -> 0 | K12: =SUM(K6:K11) -> 139320 | L12: =SUM(L6:L11) -> 0 | ... P12: =SUM(P6:P11) -> 0
A13: =+A11+1 -> 7 | B13: ห้องว่าง | C13: บ้านตลิ่งชัน | K13: =SUM(E13:J13) -> 0
A14: กรุงเทพมหานคร | E14: =SUM(E13) -> 0 | F14: =+F13 -> 0 | G14: =SUM(G13) -> 0 | H14: =+H13 -> 0 | I14: =+I13 -> 0 | J14: =SUM(J13) -> 0 | K14: =SUM(K13) -> 0 | L14: =SUM(L13) -> 0 | M14: =SUM(M13) -> 0 | N14: =SUM(N13) -> 0 | O14: =SUM(O13) -> 0 | P14: =SUM(P13) -> 0
A15: =+A13+1 -> 8 | B15: ซอยมายเฮาส์ ห้อง BP35/533 | C15: ห้องเช่าซอยมายเฮาส์ | E15: 2165 | K15: =+E15+J15 -> 2165 | P15: =+K15 -> 2165
A16: =+A15+1 -> 9 | B16: ซอยมายเฮาส์ ห้อง BP35/534 | C16: ห้องเช่าซอยมายเฮาส์ | E16: 1569 | K16: =SUM(E16:J16) -> 1569 | P16: =+K16 -> 1569
A17: =+A16+1 -> 10 | B17: ซอยมายเฮาส์ ห้อง BP35/535 | C17: ห้องเช่าซอยมายเฮาส์ | E17: 2039 | K17: =+E17 -> 2039 | P17: =+K17 -> 2039
A18: =+A17+1 -> 11 | B18: ซอยมายเฮาส์ ห้อง BP35/536 | C18: ห้องเช่าซอยมายเฮาส์ | E18: 3479 | J18: 0 | K18: =+E18+F18 -> 3479 | P18: =+K18 -> 3479
A19: =+A18+1 -> 12 | B19: ซอยมายเฮาส์ ห้อง BP35/537 | C19: ห้องเช่าซอยมายเฮาส์ | E19: 1959 | K19: =SUM(E19:J19) -> 1959 | P19: =+K19 -> 1959
A20: =+A19+1 -> 13 | B20: ซอยมายเฮาส์ ห้อง BP35/538 | C20: ห้องเช่าซอยมายเฮาส์ | E20: ห้องว่าง
A21: =+A20+1 -> 14 | B21: ซอยมายเฮาส์ ห้อง BP35/539 | C21: ห้องเช่าซอยมายเฮาส์ | E21: 1485 | K21: =+E21 -> 1485 | P21: =+K21 -> 1485
A22: =+A21+1 -> 15 | B22: ซอยมายเฮาส์ ห้อง BP35/540 | C22: ห้องเช่าซอยมายเฮาส์ | E22: 1661 | K22: =+E22 -> 1661 | P22: =+K22 -> 1661
A23: =+A22+1 -> 16 | B23: ซอยมายเฮาส์ ห้อง BP35/541 | C23: ห้องเช่าซอยมายเฮาส์ | E23: ห้องว่าง
A24: =+A23+1 -> 17 | B24: ซอยมายเฮาส์ ห้อง BP35/542 | C24: ห้องเช่าซอยมายเฮาส์ | E24: ห้องว่าง
A25: =+A24+1 -> 18 | B25: ซอยมายเฮาส์ ห้อง BP35/543 | C25: ห้องเช่าซอยมายเฮาส์ | E25: 1591 | K25: =+E25 -> 1591 | P25: =+K25 -> 1591
A26: =+A25+1 -> 19 | B26: ซอยมายเฮาส์ ห้อง BP35/544 | C26: ห้องเช่าซอยมายเฮาส์ | E26: 1861 | K26: =+E26 -> 1861 | P26: =+K26 -> 1861
A27: =+A26+1 -> 20 | B27: ซอยมายเฮาส์ ห้อง BP35/545 | C27: ห้องเช่าซอยมายเฮาส์ | E27: 2183 | K27: =+E27 -> 2183 | P27: =+K27 -> 2183
A28: =+A27+1 -> 21 | B28: ซอยมายเฮาส์ ห้อง BP35/546 | C28: ห้องเช่าซอยมายเฮาส์ | E28: 1735 | K28: =+E28 -> 1735 | P28: =+K28 -> 1735
A29: =+A28+1 -> 22 | B29: ซอยมายเฮาส์ ห้อง BP35/547 | C29: ห้องเช่าซอยมายเฮาส์ | E29: 2005 | K29: =+J29+E29 -> 2005 | P29: =+K29 -> 2005
A30: =+A29+1 -> 23 | B30: ซอยมายเฮาส์ ห้อง BP35/548 | C30: ห้องเช่าซอยมายเฮาส์ | E30: 1739 | K30: =+E30 -> 1739 | P30: =+K30 -> 1739
A31: ซอยมายเฮาส์ 16 ห้อง | E31: =SUM(E15:E30) -> 25471 | F31: =SUM(F15:F30) -> 0 | G31: =SUM(G15:G30) -> 0 | H31: =SUM(H15:H30) -> 0 | J31: =SUM(J15:J30) -> 0 | K31: =SUM(K15:K19)+K21+K22+K24+K25+K26+K27+K28+K29+K30+K23 -> 25471 | L31: =SUM(L15:L30) -> 0 | M31: =SUM(M15:M30) -> 0 | N31: =SUM(N15:N30) -> 0 | O31: =SUM(O15:O30) -> 0 | P31: =SUM(P15:P30) -> 25471
A32: =+A30+1 -> 24 | B32: อาคารพาณิชย์ ร. 9 คลินิกบ้านเลขที่ 28/7 | C32: คลินิกทันตกรรม อาคารพาณิชย์ ร.9 | E32: 27000 | K32: =SUM(E32:J32) -> 27000 | L32: 27000
A33: =+A32+1 -> 25 | B33: บจ. ดีแทค ไตรเน็ต เช่าในนามภาวิณี วังมะนาว | C33: DTAC (บ้านโป่ง) | E33: 40000 | H33: -40000 | K33: =SUM(E33:J33) -> 0 | M33: ค่าเช่ารับล่วงหน้า
A34: =+A33+1 -> 26 | B34: บ้านว่าง | C34: 190/60 หมู่ 4 ต. เบิกไพร อ. ต้อย | K34: =SUM(E34:J34) -> 0
A35: =+A34+1 -> 27 | B35: นายศิรภพ วิยาภรณ์ (ร้านนวด) | C35: บ้านตลาด 143-145 | E35: 18150 | K35: =SUM(E35:J35) -> 18150 | O35: =+K35 -> 18150
A36: =+A35+1 -> 28 | B36: นางอุษา ตันติไชยากุล | C36: บ้านท.3 401/1 ถนนทรงพล | E36: 5324 | K36: =SUM(E36:J36) -> 5324 | O36: =+K36 -> 5324
A37: =+A36+1 -> 29 | B37: น.ส.อาพร กลัดกลิ่น | C37: บ้านท.3 401/2 ถนนทรงพล | E37: 5324 | K37: =SUM(E37:J37) -> 5324 | O37: =+K37 -> 5324
A38: =+A37+1 -> 30 | B38: น.ส. เพียงตวัน อารีย์ ขายก๋วยเตี๋ยว | C38: ค่ายหลวง | E38: 3800 | K38: =SUM(E38:J38) -> 3800 | O38: 3800
A39: =+A38+1 -> 31 | B39: นายวรพล แม้นจิตต์ ขายน้ำกระท่อม | C39: ค่ายหลวง | E39: 7476 | K39: =SUM(E39:J39) -> 7476 | O39: =+K39 -> 7476
A40: =+A39+1 -> 32 | B40: น.ส. ภิญญ์วิภา ตามิ ขายหมูกระทะ | C40: ค่ายหลวง | E40: 4120 | G40: 4008 | K40: =SUM(E40:J40) -> 8128 | O40: =+K40 -> 8128
A41: =+A40+1 -> 33 | B41: น.ส. ธิดารัตน์ ตันชัยสวัสดิ์ ขายเบอร์เกอร์รี่ | C41: ค่ายหลวง | E41: 4592 | K41: =SUM(E41:J41) -> 4592 | O41: =+K41 -> 4592
...

Sheet 2-69
A1: รายละเอียดค่าเช่า
A2: ประจำเดือนกุมภาพันธ์ 2569
A4: ที่ | B4: รับเงินจาก | C4: สถานที่ | E4: รายรับ | L4: คุณนภา | M4: น.ส.ภาวิณี วังมะนาว | N4: คุณรุจิรา เกตุสถิตย์ | O4: คุณจรรยพรรศ จันทร์เครือ | P4: คุณภาวินี จอมพล
E5: ค่าเช่า | F5: บวก เงินประกัน | G5: บวก ค่าเช่าค้างจ่าย | H5: ค่าเช่ารับล่วงหน้า | I5: หัก ภาษี ณ ที่จ่าย | J5: หัก เงิน(ขาด)เกิน | K5: ยอดเงินเข้าบัญชี | L5: กสิกร 144-2-79103-8 | M5: กสิกร 119-3-21759-8 | N5: กสิกร 119-3-21471-8 | O5: SCB 611-281075-3 | P5: SCB 611-261071-1
A6: 1 | B6: คุณจินดา โกพลรัตน์ (ผู้เช่าใหม่) | C6: ทาวน์เฮ้าท์เชียงใหม่ เลขที่ 107/11 | E6: 6500 | K6: =SUM(E6:J6) -> 6500 | M6: 6500
A7: 2 | B7: คุณกมลวรรณ กลอนกลาง | C7: แยกข่วงสิงห์ เชียงใหม่ | E7: 46200 | K7: =SUM(E7:J7) -> 46200 | N7: 46200
A8: =+A7+1 -> 3 | B8: นายสมชัย พาราสรรเสริญ | C8: อู่ซ่อมรถยนต์ เชียงใหม่ | E8: 10648 | K8: =SUM(E8:J8) -> 10648 | M8: =+K8 -> 10648
A9: =+A8+1 -> 4 | B9: นางอารี อุ่นแสง | C9: ที่จอดรถ เชียงใหม่ | E9: 7986 | K9: =SUM(E9:J9) -> 7986 | M9: =+K9 -> 7986
A10: =+A9+1 -> 5 | B10: นายสิริชัย นครสิงห์ | C10: ทาวน์เฮ้าท์ เชียงใหม่ เลขที่ 107/12 | E10: 7986 | K10: =SUM(E10:J10) -> 7986 | M10: =+K10 -> 7986
A11: =+A10+1 -> 6 | B11: น.ส.นวรัตน์ เกตตะพันธุ์ (คุณปิติ) | C11: SN อพาร์ทเม้นท์ ชั้นที่ 1 | E11: 60000 | K11: =SUM(E11:J11) -> 60000 | M11: =+K11 -> 60000
A12: เชียงใหม่ | E12: =SUM(E6:E11) -> 139320 | F12: =SUM(F6:F11) -> 0 | G12: =SUM(G6:G11) -> 0 | H12: =SUM(H6:H11) -> 0 | I12: =SUM(I6:I11) -> 0 | J12: =SUM(J6:J11) -> 0 | K12: =SUM(K6:K11) -> 139320 | L12: =SUM(L6:L11) -> 0 | ... P12: =SUM(P6:P11) -> 0
A13: =+A11+1 -> 7 | B13: ห้องว่าง | C13: บ้านตลิ่งชัน | K13: =SUM(E13:J13) -> 0
A14: กรุงเทพมหานคร | E14: =SUM(E13) -> 0 | F14: =+F13 -> 0 | G14: =SUM(G13) -> 0 | H14: =+H13 -> 0 | I14: =+I13 -> 0 | J14: =SUM(J13) -> 0 | K14: =SUM(K13) -> 0 | L14: =SUM(L13) -> 0 | M14: =SUM(M13) -> 0 | N14: =SUM(N13) -> 0 | O14: =SUM(O13) -> 0 | P14: =SUM(P13) -> 0
A15: =+A13+1 -> 8 | B15: ซอยมายเฮาส์ ห้อง BP35/533 | C15: ห้องเช่าซอยมายเฮาส์ | E15: 2081 | K15: =+E15+J15 -> 2081 | P15: =+K15 -> 2081
A16: =+A15+1 -> 9 | B16: ซอยมายเฮาส์ ห้อง BP35/534 | C16: ห้องเช่าซอยมายเฮาส์ | E16: 1613 | K16: =SUM(E16:J16) -> 1613 | P16: =+K16 -> 1613
A17: =+A16+1 -> 10 | B17: ซอยมายเฮาส์ ห้อง BP35/535 | C17: ห้องเช่าซอยมายเฮาส์ | E17: 1975 | K17: =+E17 -> 1975 | P17: =+K17 -> 1975
A18: =+A17+1 -> 11 | B18: ซอยมายเฮาส์ ห้อง BP35/536 | C18: ห้องเช่าซอยมายเฮาส์ | E18: 2965 | J18: 0 | K18: =+E18+F18 -> 2965 | P18: =+K18 -> 2965
A19: =+A18+1 -> 12 | B19: ซอยมายเฮาส์ ห้อง BP35/537 | C19: ห้องเช่าซอยมายเฮาส์ | E19: 2013 | K19: =SUM(E19:J19) -> 2013 | P19: =+K19 -> 2013
A20: =+A19+1 -> 13 | B20: ซอยมายเฮาส์ ห้อง BP35/538 | C20: ห้องเช่าซอยมายเฮาส์ | E20: ห้องว่าง
A21: =+A20+1 -> 14 | B21: ซอยมายเฮาส์ ห้อง BP35/539 | C21: ห้องเช่าซอยมายเฮาส์ | E21: 1467 | K21: =+E21 -> 1467 | P21: =+K21 -> 1467
A22: =+A21+1 -> 15 | B22: ซอยมายเฮาส์ ห้อง BP35/540 | C22: ห้องเช่าซอยมายเฮาส์ | E22: 1867 | K22: =+E22 -> 1867 | P22: =+K22 -> 1867
A23: =+A22+1 -> 16 | B23: ซอยมายเฮาส์ ห้อง BP35/541 | C23: ห้องเช่าซอยมายเฮาส์ | E23: ห้องว่าง
A24: =+A23+1 -> 17 | B24: ซอยมายเฮาส์ ห้อง BP35/542 | C24: ห้องเช่าซอยมายเฮาส์ | E24: ห้องว่าง
A25: =+A24+1 -> 18 | B25: ซอยมายเฮาส์ ห้อง BP35/543 | C25: ห้องเช่าซอยมายเฮาส์ | E25: 1577 | K25: =+E25 -> 1577 | P25: =+K25 -> 1577
A26: =+A25+1 -> 19 | B26: ซอยมายเฮาส์ ห้อง BP35/544 | C26: ห้องเช่าซอยมายเฮาส์ | E26: 1905 | K26: =+E26 -> 1905 | P26: =+K26 -> 1905
A27: =+A26+1 -> 20 | B27: ซอยมายเฮาส์ ห้อง BP35/545 | C27: ห้องเช่าซอยมายเฮาส์ | E27: 2041 | K27: =+E27 -> 2041 | P27: =+K27 -> 2041
A28: =+A27+1 -> 21 | B28: ซอยมายเฮาส์ ห้อง BP35/546 | C28: ห้องเช่าซอยมายเฮาส์ | E28: 1663 | K28: =+E28 -> 1663 | P28: =+K28 -> 1663
A29: =+A28+1 -> 22 | B29: ซอยมายเฮาส์ ห้อง BP35/547 | C29: ห้องเช่าซอยมายเฮาส์ | E29: 2093 | K29: =+J29+E29 -> 2093 | P29: =+K29 -> 2093
A30: =+A29+1 -> 23 | B30: ซอยมายเฮาส์ ห้อง BP35/548 | C30: ห้องเช่าซอยมายเฮาส์ | E30: 1691 | K30: =+E30 -> 1691 | P30: =+K30 -> 1691
